ERROR 2018-08-18 10:06:19,015 exception 80 Invalid HTTP_HOST header: 'api.meiduo.site:8000'. You may need to add 'api.meiduo.site' to ALLOWED_HOSTS.
ERROR 2018-08-18 10:06:19,016 exception 80 Invalid HTTP_HOST header: 'api.meiduo.site:8000'. You may need to add 'api.meiduo.site' to ALLOWED_HOSTS.
ERROR 2018-08-18 10:06:19,016 exception 80 Invalid HTTP_HOST header: 'api.meiduo.site:8000'. You may need to add 'api.meiduo.site' to ALLOWED_HOSTS.
WARNING 2018-08-18 10:06:19,162 basehttp 124 "GET /categories/157/skus/?page=1&page_size=5&ordering=-create_time HTTP/1.1" 400 70445
WARNING 2018-08-18 10:06:19,168 basehttp 124 "OPTIONS /cart/ HTTP/1.1" 400 69695
WARNING 2018-08-18 10:06:19,172 basehttp 124 "GET /categories/157/ HTTP/1.1" 400 69498
INFO 2018-08-18 10:10:20,083 basehttp 124 "GET / HTTP/1.1" 200 1714
ERROR 2018-08-18 10:13:27,541 exception 80 Invalid HTTP_HOST header: 'api.meiduo.site:8000'. You may need to add 'api.meiduo.site' to ALLOWED_HOSTS.
WARNING 2018-08-18 10:13:27,595 basehttp 124 "GET / HTTP/1.1" 400 69973
INFO 2018-08-18 10:15:16,467 basehttp 124 "GET / HTTP/1.1" 200 1714
INFO 2018-08-18 10:18:20,433 basehttp 124 "GET / HTTP/1.1" 200 1714
ERROR 2018-08-18 10:20:47,028 exception 80 Invalid HTTP_HOST header: 'www.meiduo.site:8000'. You may need to add 'www.meiduo.site' to ALLOWED_HOSTS.
WARNING 2018-08-18 10:20:47,104 basehttp 124 "GET / HTTP/1.1" 400 69249
WARNING 2018-08-18 12:04:30,427 base 152 Not Found: /mobiles/13123456789/count/
WARNING 2018-08-18 12:04:30,431 basehttp 124 "GET /mobiles/13123456789/count/ HTTP/1.1" 404 2207
WARNING 2018-08-18 12:04:46,808 base 152 Not Found: /mobiles/13123456789/count/
WARNING 2018-08-18 12:04:46,812 base 152 Not Found: /sms_code/13123456789/
WARNING 2018-08-18 12:04:46,813 basehttp 124 "GET /mobiles/13123456789/count/ HTTP/1.1" 404 2207
WARNING 2018-08-18 12:04:46,814 basehttp 124 "GET /sms_code/13123456789/ HTTP/1.1" 404 2186
WARNING 2018-08-18 12:05:18,701 base 152 Not Found: /mobiles/13123456789/count/
WARNING 2018-08-18 12:05:18,709 basehttp 124 "GET /mobiles/13123456789/count/ HTTP/1.1" 404 2206
INFO 2018-08-18 12:05:18,706 basehttp 124 "GET /sms_code/13123456789/ HTTP/1.1" 200 16
WARNING 2018-08-18 12:05:46,551 base 152 Not Found: /mobiles/13123456782/count/
WARNING 2018-08-18 12:05:46,555 basehttp 124 "GET /mobiles/13123456782/count/ HTTP/1.1" 404 2206
WARNING 2018-08-18 12:05:53,309 base 152 Not Found: /mobiles/13123456781/count/
WARNING 2018-08-18 12:05:53,309 basehttp 124 "GET /mobiles/13123456781/count/ HTTP/1.1" 404 2206
WARNING 2018-08-18 12:05:56,951 base 152 Not Found: /mobiles/13123456781/count/
WARNING 2018-08-18 12:05:56,952 basehttp 124 "GET /mobiles/13123456781/count/ HTTP/1.1" 404 2206
INFO 2018-08-18 12:05:56,965 basehttp 124 "GET /sms_code/13123456781/ HTTP/1.1" 200 16
WARNING 2018-08-18 12:10:50,440 base 152 Not Found: /mobiles/13123456789/count/
WARNING 2018-08-18 12:10:50,441 basehttp 124 "GET /mobiles/13123456789/count/ HTTP/1.1" 404 2206
INFO 2018-08-18 12:10:52,726 basehttp 124 "GET /sms_code/13123456789/ HTTP/1.1" 200 16
WARNING 2018-08-18 12:10:52,736 base 152 Not Found: /mobiles/13123456789/count/
WARNING 2018-08-18 12:10:52,736 basehttp 124 "GET /mobiles/13123456789/count/ HTTP/1.1" 404 2206
WARNING 2018-08-19 15:18:07,601 base 152 Not Found: /
WARNING 2018-08-19 15:18:07,609 basehttp 124 "GET / HTTP/1.1" 404 2104
WARNING 2018-08-19 15:18:08,071 base 152 Not Found: /favicon.ico
WARNING 2018-08-19 15:18:08,072 basehttp 124 "GET /favicon.ico HTTP/1.1" 404 2155
INFO 2018-08-19 15:18:12,544 basehttp 124 "GET /admin HTTP/1.1" 301 0
INFO 2018-08-19 15:18:12,582 basehttp 124 "GET /admin/ HTTP/1.1" 302 0
INFO 2018-08-19 15:18:12,713 basehttp 124 "GET /admin/login/?next=/admin/ HTTP/1.1" 200 1652
INFO 2018-08-19 15:18:12,727 basehttp 124 "GET /static/admin/css/base.css HTTP/1.1" 304 0
INFO 2018-08-19 15:18:12,741 basehttp 124 "GET /static/admin/css/login.css HTTP/1.1" 304 0
INFO 2018-08-19 15:18:12,796 basehttp 124 "GET /static/admin/css/fonts.css HTTP/1.1" 304 0
INFO 2018-08-19 15:18:12,810 basehttp 124 "GET /static/admin/fonts/Roboto-Regular-webfont.woff HTTP/1.1" 304 0
INFO 2018-08-19 15:18:12,837 basehttp 124 "GET /static/admin/fonts/Roboto-Light-webfont.woff HTTP/1.1" 304 0
WARNING 2018-08-19 15:18:36,893 base 152 Not Found: /
WARNING 2018-08-19 15:18:36,894 basehttp 124 "GET / HTTP/1.1" 404 2110
WARNING 2018-08-19 15:18:36,940 base 152 Not Found: /favicon.ico
WARNING 2018-08-19 15:18:36,944 basehttp 124 "GET /favicon.ico HTTP/1.1" 404 2161
WARNING 2018-08-19 17:29:54,251 base 152 Not Found: /
WARNING 2018-08-19 17:29:54,261 basehttp 124 "GET / HTTP/1.1" 404 2104
WARNING 2018-08-19 17:29:54,476 base 152 Not Found: /favicon.ico
WARNING 2018-08-19 17:29:54,477 basehttp 124 "GET /favicon.ico HTTP/1.1" 404 2155
WARNING 2018-08-19 17:30:10,363 base 152 Not Found: /usernames/uchida/count/
WARNING 2018-08-19 17:30:10,368 basehttp 124 "GET /usernames/uchida/count/ HTTP/1.1" 404 2197
WARNING 2018-08-19 17:30:26,742 base 152 Not Found: /mobiles/13123456789/count/
WARNING 2018-08-19 17:30:26,744 basehttp 124 "GET /mobiles/13123456789/count/ HTTP/1.1" 404 2206
WARNING 2018-08-19 17:30:27,202 base 152 Not Found: /mobiles/13123456789/count/
WARNING 2018-08-19 17:30:27,206 basehttp 124 "GET /mobiles/13123456789/count/ HTTP/1.1" 404 2206
INFO 2018-08-19 17:30:27,299 basehttp 124 "GET /sms_code/13123456789/ HTTP/1.1" 200 16
WARNING 2018-08-19 17:30:42,192 base 152 Not Found: /mobiles/13123456789/count/
WARNING 2018-08-19 17:30:42,192 base 152 Not Found: /usernames/uchida/count/
WARNING 2018-08-19 17:30:42,193 basehttp 124 "GET /usernames/uchida/count/ HTTP/1.1" 404 2197
WARNING 2018-08-19 17:30:42,196 basehttp 124 "GET /mobiles/13123456789/count/ HTTP/1.1" 404 2206
INFO 2018-08-19 17:30:42,197 basehttp 124 "OPTIONS /users/ HTTP/1.1" 200 0
WARNING 2018-08-19 17:30:42,203 base 152 Not Found: /users/
WARNING 2018-08-19 17:30:42,204 basehttp 124 "POST /users/ HTTP/1.1" 404 2147
WARNING 2018-08-19 17:32:23,732 base 152 Not Found: /users/
ERROR 2018-08-19 17:32:23,736 exception 135 Internal Server Error: /usernames/uchida/count/
Traceback (most recent call last):
  File "/home/python/.virtualenvs/django_cp4/lib/python3.5/site-packages/django/core/handlers/exception.py", line 41, in inner
    response = get_response(request)
  File "/home/python/.virtualenvs/django_cp4/lib/python3.5/site-packages/django/core/handlers/base.py", line 187, in _get_response
    response = self.process_exception_by_middleware(e, request)
  File "/home/python/.virtualenvs/django_cp4/lib/python3.5/site-packages/django/core/handlers/base.py", line 185, in _get_response
    response = wrapped_callback(request, *callback_args, **callback_kwargs)
  File "/home/python/.virtualenvs/django_cp4/lib/python3.5/site-packages/django/views/decorators/csrf.py", line 58, in wrapped_view
    return view_func(*args, **kwargs)
  File "/home/python/.virtualenvs/django_cp4/lib/python3.5/site-packages/django/views/generic/base.py", line 68, in view
    return self.dispatch(request, *args, **kwargs)
  File "/home/python/.virtualenvs/django_cp4/lib/python3.5/site-packages/rest_framework/views.py", line 483, in dispatch
    response = self.handle_exception(exc)
  File "/home/python/.virtualenvs/django_cp4/lib/python3.5/site-packages/rest_framework/views.py", line 443, in handle_exception
    self.raise_uncaught_exception(exc)
  File "/home/python/.virtualenvs/django_cp4/lib/python3.5/site-packages/rest_framework/views.py", line 480, in dispatch
    response = handler(request, *args, **kwargs)
  File "/home/python/Desktop/Django_1/meiduo_api/apps/users/views.py", line 12, in get
    count = User.objects.filter(user_name = username).count()
  File "/home/python/.virtualenvs/django_cp4/lib/python3.5/site-packages/django/db/models/manager.py", line 85, in manager_method
    return getattr(self.get_queryset(), name)(*args, **kwargs)
  File "/home/python/.virtualenvs/django_cp4/lib/python3.5/site-packages/django/db/models/query.py", line 781, in filter
    return self._filter_or_exclude(False, *args, **kwargs)
  File "/home/python/.virtualenvs/django_cp4/lib/python3.5/site-packages/django/db/models/query.py", line 799, in _filter_or_exclude
    clone.query.add_q(Q(*args, **kwargs))
  File "/home/python/.virtualenvs/django_cp4/lib/python3.5/site-packages/django/db/models/sql/query.py", line 1260, in add_q
    clause, _ = self._add_q(q_object, self.used_aliases)
  File "/home/python/.virtualenvs/django_cp4/lib/python3.5/site-packages/django/db/models/sql/query.py", line 1286, in _add_q
    allow_joins=allow_joins, split_subq=split_subq,
  File "/home/python/.virtualenvs/django_cp4/lib/python3.5/site-packages/django/db/models/sql/query.py", line 1164, in build_filter
    lookups, parts, reffed_expression = self.solve_lookup_type(arg)
  File "/home/python/.virtualenvs/django_cp4/lib/python3.5/site-packages/django/db/models/sql/query.py", line 1044, in solve_lookup_type
    _, field, _, lookup_parts = self.names_to_path(lookup_splitted, self.get_meta())
  File "/home/python/.virtualenvs/django_cp4/lib/python3.5/site-packages/django/db/models/sql/query.py", line 1362, in names_to_path
    "Choices are: %s" % (name, ", ".join(available)))
django.core.exceptions.FieldError: Cannot resolve keyword 'user_name' into field. Choices are: date_joined, email, first_name, groups, id, is_active, is_staff, is_superuser, last_login, last_name, logentry, mobile, password, user_permissions, username
WARNING 2018-08-19 17:32:23,738 basehttp 124 "POST /users/ HTTP/1.1" 404 2536
ERROR 2018-08-19 17:32:23,765 exceptions 25 [<users.views.MobileCountView object at 0x7f8a4a46dbe0>] (1146, "Table 'meiduo_demo.tb_users' doesn't exist")
ERROR 2018-08-19 17:32:23,766 basehttp 124 "GET /mobiles/13123456789/count/ HTTP/1.1" 507 35
ERROR 2018-08-19 17:32:23,854 basehttp 124 "GET /usernames/uchida/count/ HTTP/1.1" 500 19416
ERROR 2018-08-19 17:32:27,721 exceptions 25 [<users.views.MobileCountView object at 0x7f8a4a46da58>] (1146, "Table 'meiduo_demo.tb_users' doesn't exist")
ERROR 2018-08-19 17:32:27,731 basehttp 124 "GET /mobiles/13123456789/count/ HTTP/1.1" 507 35
ERROR 2018-08-19 17:32:47,411 exceptions 25 [<users.views.MobileCountView object at 0x7f5570eb55c0>] (1146, "Table 'meiduo_demo.tb_users' doesn't exist")
ERROR 2018-08-19 17:32:47,413 basehttp 124 "GET /mobiles/13123456789/count/ HTTP/1.1" 507 35
WARNING 2018-08-19 17:32:47,513 base 152 Not Found: /users/
ERROR 2018-08-19 17:32:47,519 exceptions 25 [<users.views.MobileCountView object at 0x7f5572ad7898>] (1146, "Table 'meiduo_demo.tb_users' doesn't exist")
ERROR 2018-08-19 17:32:47,520 basehttp 124 "GET /mobiles/13123456789/count/ HTTP/1.1" 507 35
ERROR 2018-08-19 17:32:47,521 exceptions 25 [<users.views.UsernameCountView object at 0x7f5570578198>] (1146, "Table 'meiduo_demo.tb_users' doesn't exist")
ERROR 2018-08-19 17:32:47,521 basehttp 124 "GET /usernames/uchida/count/ HTTP/1.1" 507 35
WARNING 2018-08-19 17:32:47,523 basehttp 124 "POST /users/ HTTP/1.1" 404 2536
ERROR 2018-08-19 17:33:10,157 exceptions 25 [<users.views.MobileCountView object at 0x7f5570588a90>] (1146, "Table 'meiduo_demo.tb_users' doesn't exist")
ERROR 2018-08-19 17:33:10,159 basehttp 124 "GET /mobiles/13123456789/count/ HTTP/1.1" 507 35
INFO 2018-08-19 17:33:10,216 basehttp 124 "GET /sms_code/13123456789/ HTTP/1.1" 200 16
WARNING 2018-08-19 17:33:33,817 base 152 Not Found: /users/
WARNING 2018-08-19 17:33:33,823 basehttp 124 "POST /users/ HTTP/1.1" 404 2536
ERROR 2018-08-19 17:33:33,823 exceptions 25 [<users.views.UsernameCountView object at 0x7f5570212320>] (1146, "Table 'meiduo_demo.tb_users' doesn't exist")
ERROR 2018-08-19 17:33:33,824 basehttp 124 "GET /usernames/uchida/count/ HTTP/1.1" 507 35
ERROR 2018-08-19 17:33:33,826 exceptions 25 [<users.views.MobileCountView object at 0x7f5570217160>] (1146, "Table 'meiduo_demo.tb_users' doesn't exist")
ERROR 2018-08-19 17:33:33,827 basehttp 124 "GET /mobiles/13123456789/count/ HTTP/1.1" 507 35
WARNING 2018-08-19 17:33:38,020 base 152 Not Found: /users/
WARNING 2018-08-19 17:33:38,022 basehttp 124 "POST /users/ HTTP/1.1" 404 2536
ERROR 2018-08-19 17:33:38,036 exceptions 25 [<users.views.UsernameCountView object at 0x7f557021f6d8>] (1146, "Table 'meiduo_demo.tb_users' doesn't exist")
ERROR 2018-08-19 17:33:38,039 basehttp 124 "GET /usernames/uchida/count/ HTTP/1.1" 507 35
ERROR 2018-08-19 17:33:38,044 exceptions 25 [<users.views.MobileCountView object at 0x7f557022a5f8>] (1146, "Table 'meiduo_demo.tb_users' doesn't exist")
ERROR 2018-08-19 17:33:38,048 basehttp 124 "GET /mobiles/13123456789/count/ HTTP/1.1" 507 35
WARNING 2018-08-19 17:33:38,618 base 152 Not Found: /users/
ERROR 2018-08-19 17:33:38,623 exceptions 25 [<users.views.UsernameCountView object at 0x7f557025eeb8>] (1146, "Table 'meiduo_demo.tb_users' doesn't exist")
ERROR 2018-08-19 17:33:38,624 basehttp 124 "GET /usernames/uchida/count/ HTTP/1.1" 507 35
ERROR 2018-08-19 17:33:38,626 exceptions 25 [<users.views.MobileCountView object at 0x7f5570217898>] (1146, "Table 'meiduo_demo.tb_users' doesn't exist")
ERROR 2018-08-19 17:33:38,626 basehttp 124 "GET /mobiles/13123456789/count/ HTTP/1.1" 507 35
WARNING 2018-08-19 17:33:38,628 basehttp 124 "POST /users/ HTTP/1.1" 404 2536
ERROR 2018-08-19 17:33:40,676 exceptions 25 [<users.views.UsernameCountView object at 0x7f5570224080>] (1146, "Table 'meiduo_demo.tb_users' doesn't exist")
ERROR 2018-08-19 17:33:40,679 basehttp 124 "GET /usernames/uchida/count/ HTTP/1.1" 507 35
WARNING 2018-08-19 17:33:56,404 base 152 Not Found: /users
WARNING 2018-08-19 17:33:56,416 basehttp 124 "GET /users HTTP/1.1" 404 2526
WARNING 2018-08-19 17:34:00,449 base 152 Not Found: /user
WARNING 2018-08-19 17:34:00,450 basehttp 124 "GET /user HTTP/1.1" 404 2523
ERROR 2018-08-19 17:34:59,028 exceptions 25 [<users.views.UsernameCountView object at 0x7f5570eb53c8>] (1146, "Table 'meiduo_demo.tb_users' doesn't exist")
ERROR 2018-08-19 17:34:59,030 basehttp 124 "GET /usernames/uchida/count/ HTTP/1.1" 507 35
ERROR 2018-08-19 17:35:08,223 exceptions 25 [<users.views.MobileCountView object at 0x7f55705cdf60>] (1146, "Table 'meiduo_demo.tb_users' doesn't exist")
ERROR 2018-08-19 17:35:08,225 basehttp 124 "GET /mobiles/13123456789/count/ HTTP/1.1" 507 35
ERROR 2018-08-19 17:35:10,189 exceptions 25 [<users.views.MobileCountView object at 0x7f5570224978>] (1146, "Table 'meiduo_demo.tb_users' doesn't exist")
ERROR 2018-08-19 17:35:10,192 basehttp 124 "GET /mobiles/13123456789/count/ HTTP/1.1" 507 35
INFO 2018-08-19 17:35:10,203 basehttp 124 "GET /sms_code/13123456789/ HTTP/1.1" 200 16
WARNING 2018-08-19 17:35:29,762 base 152 Not Found: /users/
ERROR 2018-08-19 17:35:29,763 exceptions 25 [<users.views.UsernameCountView object at 0x7f5570212e10>] (1146, "Table 'meiduo_demo.tb_users' doesn't exist")
ERROR 2018-08-19 17:35:29,765 basehttp 124 "GET /usernames/uchida/count/ HTTP/1.1" 507 35
ERROR 2018-08-19 17:35:29,767 exceptions 25 [<users.views.MobileCountView object at 0x7f557058f518>] (1146, "Table 'meiduo_demo.tb_users' doesn't exist")
ERROR 2018-08-19 17:35:29,767 basehttp 124 "GET /mobiles/13123456789/count/ HTTP/1.1" 507 35
WARNING 2018-08-19 17:35:29,770 basehttp 124 "POST /users/ HTTP/1.1" 404 2536
WARNING 2018-08-19 17:35:31,761 base 152 Not Found: /users/
WARNING 2018-08-19 17:35:31,768 basehttp 124 "POST /users/ HTTP/1.1" 404 2536
ERROR 2018-08-19 17:35:31,770 exceptions 25 [<users.views.MobileCountView object at 0x7f5570232e80>] (1146, "Table 'meiduo_demo.tb_users' doesn't exist")
ERROR 2018-08-19 17:35:31,772 basehttp 124 "GET /mobiles/13123456789/count/ HTTP/1.1" 507 35
ERROR 2018-08-19 17:35:31,773 exceptions 25 [<users.views.UsernameCountView object at 0x7f557021bef0>] (1146, "Table 'meiduo_demo.tb_users' doesn't exist")
ERROR 2018-08-19 17:35:31,774 basehttp 124 "GET /usernames/uchida/count/ HTTP/1.1" 507 35
ERROR 2018-08-19 17:37:37,098 exceptions 25 [<users.views.UsernameCountView object at 0x7f55702348d0>] (1146, "Table 'meiduo_demo.tb_users' doesn't exist")
ERROR 2018-08-19 17:37:37,104 basehttp 124 "GET /usernames/uchida/count/ HTTP/1.1" 507 35
ERROR 2018-08-19 17:37:49,437 exceptions 25 [<users.views.MobileCountView object at 0x7f557021b278>] (1146, "Table 'meiduo_demo.tb_users' doesn't exist")
ERROR 2018-08-19 17:37:49,440 basehttp 124 "GET /mobiles/13123456788/count/ HTTP/1.1" 507 35
ERROR 2018-08-19 17:37:50,183 exceptions 25 [<users.views.MobileCountView object at 0x7f557023d198>] (1146, "Table 'meiduo_demo.tb_users' doesn't exist")
ERROR 2018-08-19 17:37:50,186 basehttp 124 "GET /mobiles/13123456788/count/ HTTP/1.1" 507 35
INFO 2018-08-19 17:37:50,187 basehttp 124 "GET /sms_code/13123456788/ HTTP/1.1" 200 16
WARNING 2018-08-19 17:37:54,000 basehttp 124 "GET /sms_code/13123456788/ HTTP/1.1" 400 37
ERROR 2018-08-19 17:37:54,006 exceptions 25 [<users.views.MobileCountView object at 0x7f5570234780>] (1146, "Table 'meiduo_demo.tb_users' doesn't exist")
ERROR 2018-08-19 17:37:54,008 basehttp 124 "GET /mobiles/13123456788/count/ HTTP/1.1" 507 35
ERROR 2018-08-19 17:38:19,771 exceptions 25 [<users.views.UsernameCountView object at 0x7f5570280f60>] (1146, "Table 'meiduo_demo.tb_users' doesn't exist")
ERROR 2018-08-19 17:38:19,773 basehttp 124 "GET /usernames/uchida/count/ HTTP/1.1" 507 35
INFO 2018-08-19 17:38:19,774 basehttp 124 "OPTIONS /users/ HTTP/1.1" 200 0
ERROR 2018-08-19 17:38:19,778 exceptions 25 [<users.views.MobileCountView object at 0x7f55702417b8>] (1146, "Table 'meiduo_demo.tb_users' doesn't exist")
ERROR 2018-08-19 17:38:19,779 basehttp 124 "GET /mobiles/13123456788/count/ HTTP/1.1" 507 35
INFO 2018-08-19 17:38:36,824 basehttp 124 "OPTIONS /users/ HTTP/1.1" 200 0
ERROR 2018-08-19 17:38:36,841 exceptions 25 [<users.views.UsernameCountView object at 0x7f55702344e0>] (1146, "Table 'meiduo_demo.tb_users' doesn't exist")
ERROR 2018-08-19 17:38:36,845 basehttp 124 "GET /usernames/uchida/count/ HTTP/1.1" 507 35
ERROR 2018-08-19 17:38:36,852 exceptions 25 [<users.views.MobileCountView object at 0x7f5570241e80>] (1146, "Table 'meiduo_demo.tb_users' doesn't exist")
ERROR 2018-08-19 17:38:36,856 basehttp 124 "GET /mobiles/13123456788/count/ HTTP/1.1" 507 35
ERROR 2018-08-19 17:38:37,773 exceptions 25 [<users.views.UsernameCountView object at 0x7f5570244d30>] (1146, "Table 'meiduo_demo.tb_users' doesn't exist")
INFO 2018-08-19 17:38:37,776 basehttp 124 "OPTIONS /users/ HTTP/1.1" 200 0
ERROR 2018-08-19 17:38:37,780 basehttp 124 "GET /usernames/uchida/count/ HTTP/1.1" 507 35
ERROR 2018-08-19 17:38:37,781 exceptions 25 [<users.views.MobileCountView object at 0x7f5570238da0>] (1146, "Table 'meiduo_demo.tb_users' doesn't exist")
ERROR 2018-08-19 17:38:37,787 basehttp 124 "GET /mobiles/13123456788/count/ HTTP/1.1" 507 35
ERROR 2018-08-19 17:38:38,425 exceptions 25 [<users.views.UsernameCountView object at 0x7f557023dcc0>] (1146, "Table 'meiduo_demo.tb_users' doesn't exist")
ERROR 2018-08-19 17:38:38,430 basehttp 124 "GET /usernames/uchida/count/ HTTP/1.1" 507 35
INFO 2018-08-19 17:38:38,432 basehttp 124 "OPTIONS /users/ HTTP/1.1" 200 0
ERROR 2018-08-19 17:38:38,434 exceptions 25 [<users.views.MobileCountView object at 0x7f5570241e48>] (1146, "Table 'meiduo_demo.tb_users' doesn't exist")
ERROR 2018-08-19 17:38:38,436 basehttp 124 "GET /mobiles/13123456788/count/ HTTP/1.1" 507 35
ERROR 2018-08-19 17:38:38,627 exceptions 25 [<users.views.UsernameCountView object at 0x7f5570234240>] (1146, "Table 'meiduo_demo.tb_users' doesn't exist")
ERROR 2018-08-19 17:38:38,631 basehttp 124 "GET /usernames/uchida/count/ HTTP/1.1" 507 35
INFO 2018-08-19 17:38:38,634 basehttp 124 "OPTIONS /users/ HTTP/1.1" 200 0
ERROR 2018-08-19 17:38:38,635 exceptions 25 [<users.views.MobileCountView object at 0x7f5570244208>] (1146, "Table 'meiduo_demo.tb_users' doesn't exist")
ERROR 2018-08-19 17:38:38,639 basehttp 124 "GET /mobiles/13123456788/count/ HTTP/1.1" 507 35
ERROR 2018-08-19 17:38:38,809 exceptions 25 [<users.views.UsernameCountView object at 0x7f55701cd940>] (1146, "Table 'meiduo_demo.tb_users' doesn't exist")
ERROR 2018-08-19 17:38:38,812 basehttp 124 "GET /usernames/uchida/count/ HTTP/1.1" 507 35
INFO 2018-08-19 17:38:38,813 basehttp 124 "OPTIONS /users/ HTTP/1.1" 200 0
ERROR 2018-08-19 17:38:38,819 exceptions 25 [<users.views.MobileCountView object at 0x7f55702447b8>] (1146, "Table 'meiduo_demo.tb_users' doesn't exist")
ERROR 2018-08-19 17:38:38,820 basehttp 124 "GET /mobiles/13123456788/count/ HTTP/1.1" 507 35
INFO 2018-08-19 17:38:46,161 basehttp 124 "OPTIONS /users/ HTTP/1.1" 200 0
ERROR 2018-08-19 17:38:46,181 exceptions 25 [<users.views.UsernameCountView object at 0x7f557023d390>] (1146, "Table 'meiduo_demo.tb_users' doesn't exist")
ERROR 2018-08-19 17:38:46,188 basehttp 124 "GET /usernames/uchida/count/ HTTP/1.1" 507 35
ERROR 2018-08-19 17:38:46,198 exceptions 25 [<users.views.MobileCountView object at 0x7f5570241ac8>] (1146, "Table 'meiduo_demo.tb_users' doesn't exist")
ERROR 2018-08-19 17:38:46,200 basehttp 124 "GET /mobiles/13123456788/count/ HTTP/1.1" 507 35
ERROR 2018-08-19 17:38:59,332 exceptions 25 [<users.views.MobileCountView object at 0x7f557021b3c8>] (1146, "Table 'meiduo_demo.tb_users' doesn't exist")
ERROR 2018-08-19 17:38:59,427 basehttp 124 "GET /mobiles/13123456788/count/ HTTP/1.1" 507 5265
INFO 2018-08-19 17:38:59,446 basehttp 124 "GET /static/rest_framework/css/bootstrap-tweaks.css HTTP/1.1" 200 3385
INFO 2018-08-19 17:38:59,451 basehttp 124 "GET /static/rest_framework/css/bootstrap.min.css HTTP/1.1" 200 121200
INFO 2018-08-19 17:38:59,460 basehttp 124 "GET /static/rest_framework/css/prettify.css HTTP/1.1" 200 817
INFO 2018-08-19 17:38:59,476 basehttp 124 "GET /static/rest_framework/css/default.css HTTP/1.1" 200 1131
INFO 2018-08-19 17:38:59,487 basehttp 124 "GET /static/rest_framework/js/ajax-form.js HTTP/1.1" 200 3597
INFO 2018-08-19 17:38:59,488 basehttp 124 "GET /static/rest_framework/js/jquery-3.3.1.min.js HTTP/1.1" 200 86927
INFO 2018-08-19 17:38:59,496 basehttp 124 "GET /static/rest_framework/js/csrf.js HTTP/1.1" 200 1735
INFO 2018-08-19 17:38:59,505 basehttp 124 "GET /static/rest_framework/js/bootstrap.min.js HTTP/1.1" 200 37045
INFO 2018-08-19 17:38:59,516 basehttp 124 "GET /static/rest_framework/js/prettify-min.js HTTP/1.1" 200 13632
INFO 2018-08-19 17:38:59,520 basehttp 124 "GET /static/rest_framework/js/default.js HTTP/1.1" 200 1262
INFO 2018-08-19 17:38:59,538 basehttp 124 "GET /static/rest_framework/img/grid.png HTTP/1.1" 200 1458
WARNING 2018-08-19 17:38:59,795 base 152 Not Found: /favicon.ico
WARNING 2018-08-19 17:38:59,796 basehttp 124 "GET /favicon.ico HTTP/1.1" 404 2550
INFO 2018-08-19 17:39:09,709 basehttp 124 "OPTIONS /mobiles/13123456788/count/ HTTP/1.1" 200 5550
INFO 2018-08-19 17:41:15,504 basehttp 124 "OPTIONS /users/ HTTP/1.1" 200 0
ERROR 2018-08-19 17:41:15,612 exceptions 25 [<users.views.UsernameCountView object at 0x7f507a2ba278>] (1146, "Table 'meiduo_demo.tb_users' doesn't exist")
ERROR 2018-08-19 17:41:15,613 basehttp 124 "GET /usernames/uchida/count/ HTTP/1.1" 507 35
ERROR 2018-08-19 17:41:15,616 exceptions 25 [<users.views.MobileCountView object at 0x7f50787b37f0>] (1146, "Table 'meiduo_demo.tb_users' doesn't exist")
ERROR 2018-08-19 17:41:15,617 basehttp 124 "GET /mobiles/13123456788/count/ HTTP/1.1" 507 35
ERROR 2018-08-19 17:42:39,420 exceptions 25 [<users.views.MobileCountView object at 0x7f4d024e5588>] (1146, "Table 'meiduo_demo.tb_users' doesn't exist")
ERROR 2018-08-19 17:42:39,426 basehttp 124 "GET /mobiles/13123456788/count/ HTTP/1.1" 507 35
INFO 2018-08-19 17:42:39,545 basehttp 124 "GET /sms_code/13123456788/ HTTP/1.1" 200 16
WARNING 2018-08-19 17:42:46,298 basehttp 124 "GET /sms_code/13123456788/ HTTP/1.1" 400 37
ERROR 2018-08-19 17:42:46,310 exceptions 25 [<users.views.MobileCountView object at 0x7f4d021205c0>] (1146, "Table 'meiduo_demo.tb_users' doesn't exist")
ERROR 2018-08-19 17:42:46,317 basehttp 124 "GET /mobiles/13123456788/count/ HTTP/1.1" 507 35
ERROR 2018-08-19 17:43:07,590 exceptions 25 [<users.views.MobileCountView object at 0x7f4d0212a630>] (1146, "Table 'meiduo_demo.tb_users' doesn't exist")
ERROR 2018-08-19 17:43:07,606 basehttp 124 "GET /mobiles/13123456786/count/ HTTP/1.1" 507 35
ERROR 2018-08-19 17:43:07,693 exceptions 25 [<users.views.MobileCountView object at 0x7f4d02120ba8>] (1146, "Table 'meiduo_demo.tb_users' doesn't exist")
ERROR 2018-08-19 17:43:07,697 basehttp 124 "GET /mobiles/13123456786/count/ HTTP/1.1" 507 35
INFO 2018-08-19 17:43:07,710 basehttp 124 "GET /sms_code/13123456786/ HTTP/1.1" 200 16
ERROR 2018-08-19 17:43:15,558 exceptions 25 [<users.views.MobileCountView object at 0x7f4d021317b8>] (1146, "Table 'meiduo_demo.tb_users' doesn't exist")
ERROR 2018-08-19 17:43:15,568 basehttp 124 "GET /mobiles/13123456786/count/ HTTP/1.1" 507 35
WARNING 2018-08-19 17:43:33,627 base 152 Not Found: /mobiles/
WARNING 2018-08-19 17:43:33,635 basehttp 124 "GET /mobiles/ HTTP/1.1" 404 2697
ERROR 2018-08-19 17:43:44,069 exceptions 25 [<users.views.UsernameCountView object at 0x7f4d0212a160>] (1146, "Table 'meiduo_demo.tb_users' doesn't exist")
ERROR 2018-08-19 17:43:44,073 basehttp 124 "GET /usernames/uchida/count/ HTTP/1.1" 507 35
ERROR 2018-08-19 17:43:55,435 exceptions 25 [<users.views.MobileCountView object at 0x7f4d02193f28>] (1146, "Table 'meiduo_demo.tb_users' doesn't exist")
ERROR 2018-08-19 17:43:55,450 basehttp 124 "GET /mobiles/17695566006/count/ HTTP/1.1" 507 35
ERROR 2018-08-19 17:44:02,544 exceptions 25 [<users.views.UsernameCountView object at 0x7f4d02193a58>] (1146, "Table 'meiduo_demo.tb_users' doesn't exist")
ERROR 2018-08-19 17:44:02,620 basehttp 124 "GET /usernames/uchida/count/ HTTP/1.1" 507 5261
ERROR 2018-08-19 17:44:11,915 exceptions 25 [<users.views.UsernameCountView object at 0x7f4d02159400>] (1146, "Table 'meiduo_demo.tb_users' doesn't exist")
ERROR 2018-08-19 17:44:11,925 basehttp 124 "GET /usernames/houjie123/count/ HTTP/1.1" 507 35
ERROR 2018-08-19 17:45:31,981 exceptions 25 [<users.views.MobileCountView object at 0x7f4d0215b8d0>] (1146, "Table 'meiduo_demo.tb_users' doesn't exist")
ERROR 2018-08-19 17:45:31,990 basehttp 124 "GET /mobiles/17695566006/count/ HTTP/1.1" 507 35
ERROR 2018-08-19 17:47:27,311 exceptions 25 [<users.views.UsernameCountView object at 0x7f631e8a01d0>] (1146, "Table 'meiduo_demo.tb_users' doesn't exist")
ERROR 2018-08-19 17:47:27,312 basehttp 124 "GET /usernames/houjie123/count/ HTTP/1.1" 507 35
ERROR 2018-08-19 17:47:28,359 exceptions 25 [<users.views.UsernameCountView object at 0x7f631df622e8>] (1146, "Table 'meiduo_demo.tb_users' doesn't exist")
ERROR 2018-08-19 17:47:28,359 basehttp 124 "GET /usernames/houjie123/count/ HTTP/1.1" 507 35
ERROR 2018-08-19 17:48:36,815 exceptions 25 [<users.views.UsernameCountView object at 0x7f79b63cfdd8>] (1146, "Table 'meiduo_demo.tb_users' doesn't exist")
ERROR 2018-08-19 17:48:36,825 basehttp 124 "GET /usernames/houjie123/count/ HTTP/1.1" 507 35
ERROR 2018-08-19 17:48:41,496 exceptions 25 [<users.views.UsernameCountView object at 0x7f79b6301278>] (1146, "Table 'meiduo_demo.tb_users' doesn't exist")
ERROR 2018-08-19 17:48:41,508 basehttp 124 "GET /usernames/houjie123/count/ HTTP/1.1" 507 35
ERROR 2018-08-19 17:48:50,659 exceptions 25 [<users.views.UsernameCountView object at 0x7f79b6301a58>] (1146, "Table 'meiduo_demo.tb_users' doesn't exist")
ERROR 2018-08-19 17:48:50,677 basehttp 124 "GET /usernames/qwerty/count/ HTTP/1.1" 507 35
ERROR 2018-08-19 17:51:18,861 exceptions 25 [<users.views.UsernameCountView object at 0x7f71899f7198>] (1146, "Table 'meiduo_demo.tb_users' doesn't exist")
ERROR 2018-08-19 17:51:18,871 basehttp 124 "GET /usernames/qwerty/count/ HTTP/1.1" 507 35
ERROR 2018-08-19 17:51:22,404 exceptions 25 [<users.views.UsernameCountView object at 0x7f71890b6320>] (1146, "Table 'meiduo_demo.tb_users' doesn't exist")
ERROR 2018-08-19 17:51:22,419 basehttp 124 "GET /usernames/qwerty/count/ HTTP/1.1" 507 35
ERROR 2018-08-19 17:59:53,750 exception 135 Internal Server Error: /usernames/qwerty/count/
Traceback (most recent call last):
  File "/home/python/.virtualenvs/django_cp4/lib/python3.5/site-packages/django/core/handlers/exception.py", line 41, in inner
    response = get_response(request)
  File "/home/python/.virtualenvs/django_cp4/lib/python3.5/site-packages/django/core/handlers/base.py", line 187, in _get_response
    response = self.process_exception_by_middleware(e, request)
  File "/home/python/.virtualenvs/django_cp4/lib/python3.5/site-packages/django/core/handlers/base.py", line 185, in _get_response
    response = wrapped_callback(request, *callback_args, **callback_kwargs)
  File "/home/python/.virtualenvs/django_cp4/lib/python3.5/site-packages/django/views/decorators/csrf.py", line 58, in wrapped_view
    return view_func(*args, **kwargs)
  File "/home/python/.virtualenvs/django_cp4/lib/python3.5/site-packages/django/views/generic/base.py", line 68, in view
    return self.dispatch(request, *args, **kwargs)
  File "/home/python/.virtualenvs/django_cp4/lib/python3.5/site-packages/rest_framework/views.py", line 485, in dispatch
    self.response = self.finalize_response(request, response, *args, **kwargs)
  File "/home/python/.virtualenvs/django_cp4/lib/python3.5/site-packages/rest_framework/views.py", line 400, in finalize_response
    % type(response)
AssertionError: Expected a `Response`, `HttpResponse` or `HttpStreamingResponse` to be returned from the view, but received a `<class 'NoneType'>`
ERROR 2018-08-19 17:59:53,844 basehttp 124 "GET /usernames/qwerty/count/ HTTP/1.1" 500 87392
ERROR 2018-08-19 17:59:56,340 exception 135 Internal Server Error: /usernames/qwerty/count/
Traceback (most recent call last):
  File "/home/python/.virtualenvs/django_cp4/lib/python3.5/site-packages/django/core/handlers/exception.py", line 41, in inner
    response = get_response(request)
  File "/home/python/.virtualenvs/django_cp4/lib/python3.5/site-packages/django/core/handlers/base.py", line 187, in _get_response
    response = self.process_exception_by_middleware(e, request)
  File "/home/python/.virtualenvs/django_cp4/lib/python3.5/site-packages/django/core/handlers/base.py", line 185, in _get_response
    response = wrapped_callback(request, *callback_args, **callback_kwargs)
  File "/home/python/.virtualenvs/django_cp4/lib/python3.5/site-packages/django/views/decorators/csrf.py", line 58, in wrapped_view
    return view_func(*args, **kwargs)
  File "/home/python/.virtualenvs/django_cp4/lib/python3.5/site-packages/django/views/generic/base.py", line 68, in view
    return self.dispatch(request, *args, **kwargs)
  File "/home/python/.virtualenvs/django_cp4/lib/python3.5/site-packages/rest_framework/views.py", line 485, in dispatch
    self.response = self.finalize_response(request, response, *args, **kwargs)
  File "/home/python/.virtualenvs/django_cp4/lib/python3.5/site-packages/rest_framework/views.py", line 400, in finalize_response
    % type(response)
AssertionError: Expected a `Response`, `HttpResponse` or `HttpStreamingResponse` to be returned from the view, but received a `<class 'NoneType'>`
ERROR 2018-08-19 17:59:56,451 basehttp 124 "GET /usernames/qwerty/count/ HTTP/1.1" 500 87392
ERROR 2018-08-19 18:01:58,034 exceptions 25 [<users.views.UsernameCountView object at 0x7f4114cecda0>] (1146, "Table 'meiduo_demo.tb_users' doesn't exist")
ERROR 2018-08-19 18:01:58,036 basehttp 124 "GET /usernames/qwerty/count/ HTTP/1.1" 507 35
ERROR 2018-08-19 18:20:37,848 exception 135 Internal Server Error: /usernames/qwerty/count/
Traceback (most recent call last):
  File "/home/python/.virtualenvs/django_cp4/lib/python3.5/site-packages/django/core/handlers/exception.py", line 41, in inner
    response = get_response(request)
  File "/home/python/.virtualenvs/django_cp4/lib/python3.5/site-packages/django/core/handlers/base.py", line 187, in _get_response
    response = self.process_exception_by_middleware(e, request)
  File "/home/python/.virtualenvs/django_cp4/lib/python3.5/site-packages/django/core/handlers/base.py", line 185, in _get_response
    response = wrapped_callback(request, *callback_args, **callback_kwargs)
  File "/home/python/.virtualenvs/django_cp4/lib/python3.5/site-packages/django/views/decorators/csrf.py", line 58, in wrapped_view
    return view_func(*args, **kwargs)
  File "/home/python/.virtualenvs/django_cp4/lib/python3.5/site-packages/django/views/generic/base.py", line 68, in view
    return self.dispatch(request, *args, **kwargs)
  File "/home/python/.virtualenvs/django_cp4/lib/python3.5/site-packages/rest_framework/views.py", line 485, in dispatch
    self.response = self.finalize_response(request, response, *args, **kwargs)
  File "/home/python/.virtualenvs/django_cp4/lib/python3.5/site-packages/rest_framework/views.py", line 400, in finalize_response
    % type(response)
AssertionError: Expected a `Response`, `HttpResponse` or `HttpStreamingResponse` to be returned from the view, but received a `<class 'NoneType'>`
ERROR 2018-08-19 18:20:37,944 basehttp 124 "GET /usernames/qwerty/count/ HTTP/1.1" 500 87392
INFO 2018-08-19 18:22:03,980 basehttp 124 "GET /usernames/qwerty/count/ HTTP/1.1" 200 32
INFO 2018-08-19 18:22:04,735 basehttp 124 "GET /usernames/qwerty/count/ HTTP/1.1" 200 32
INFO 2018-08-19 18:22:12,090 basehttp 124 "GET /usernames/qwerty/count/ HTTP/1.1" 200 32
INFO 2018-08-19 18:22:25,545 basehttp 124 "GET /mobiles/13123456789/count/ HTTP/1.1" 200 34
INFO 2018-08-19 18:22:26,748 basehttp 124 "GET /mobiles/13123456789/count/ HTTP/1.1" 200 34
INFO 2018-08-19 18:22:26,826 basehttp 124 "GET /sms_code/13123456789/ HTTP/1.1" 200 16
INFO 2018-08-19 18:22:50,689 basehttp 124 "GET /usernames/qwerty/count/ HTTP/1.1" 200 32
INFO 2018-08-19 18:22:50,694 basehttp 124 "GET /mobiles/13123456789/count/ HTTP/1.1" 200 34
INFO 2018-08-19 18:23:04,611 basehttp 124 "GET /usernames/qwerty/count/ HTTP/1.1" 200 32
INFO 2018-08-19 18:23:04,621 basehttp 124 "GET /mobiles/13123456789/count/ HTTP/1.1" 200 34
INFO 2018-08-19 18:23:14,449 basehttp 124 "GET /usernames/qwerty/count/ HTTP/1.1" 200 32
INFO 2018-08-19 18:23:14,461 basehttp 124 "GET /mobiles/13123456789/count/ HTTP/1.1" 200 34
INFO 2018-08-19 18:23:14,463 basehttp 124 "OPTIONS /users/ HTTP/1.1" 200 0
WARNING 2018-08-19 18:23:14,500 basehttp 124 "POST /users/ HTTP/1.1" 400 43
INFO 2018-08-19 18:23:39,096 basehttp 124 "OPTIONS /users/ HTTP/1.1" 200 0
INFO 2018-08-19 18:23:39,122 basehttp 124 "GET /usernames/qwerty/count/ HTTP/1.1" 200 32
INFO 2018-08-19 18:23:39,125 basehttp 124 "GET /mobiles/13123456789/count/ HTTP/1.1" 200 34
WARNING 2018-08-19 18:23:39,158 basehttp 124 "POST /users/ HTTP/1.1" 400 43
INFO 2018-08-19 18:23:48,577 basehttp 124 "GET /mobiles/13123456789/count/ HTTP/1.1" 200 34
INFO 2018-08-19 18:23:48,588 basehttp 124 "GET /sms_code/13123456789/ HTTP/1.1" 200 16
INFO 2018-08-19 18:24:06,935 basehttp 124 "OPTIONS /users/ HTTP/1.1" 200 0
INFO 2018-08-19 18:24:06,952 basehttp 124 "GET /usernames/qwerty/count/ HTTP/1.1" 200 32
INFO 2018-08-19 18:24:06,956 basehttp 124 "GET /mobiles/13123456789/count/ HTTP/1.1" 200 34
WARNING 2018-08-19 18:24:06,981 basehttp 124 "POST /users/ HTTP/1.1" 400 43
INFO 2018-08-19 18:28:15,548 basehttp 124 "GET /mobiles/13123456789/count/ HTTP/1.1" 200 34
INFO 2018-08-19 18:28:15,561 basehttp 124 "GET /sms_code/13123456789/ HTTP/1.1" 200 16
INFO 2018-08-19 18:28:17,480 basehttp 124 "OPTIONS /users/ HTTP/1.1" 200 0
INFO 2018-08-19 18:28:17,486 basehttp 124 "GET /usernames/qwerty/count/ HTTP/1.1" 200 32
INFO 2018-08-19 18:28:17,507 basehttp 124 "GET /mobiles/13123456789/count/ HTTP/1.1" 200 34
WARNING 2018-08-19 18:28:17,532 basehttp 124 "POST /users/ HTTP/1.1" 400 43
INFO 2018-08-19 18:28:40,076 basehttp 124 "GET /usernames/qwerty/count/ HTTP/1.1" 200 32
INFO 2018-08-19 18:28:40,079 basehttp 124 "OPTIONS /users/ HTTP/1.1" 200 0
INFO 2018-08-19 18:28:40,098 basehttp 124 "GET /mobiles/13123456789/count/ HTTP/1.1" 200 34
WARNING 2018-08-19 18:28:40,127 basehttp 124 "POST /users/ HTTP/1.1" 400 43
INFO 2018-08-19 18:31:16,099 basehttp 124 "GET /mobiles/13123456789/count/ HTTP/1.1" 200 34
INFO 2018-08-19 18:31:16,221 basehttp 124 "GET /sms_code/13123456789/ HTTP/1.1" 200 16
INFO 2018-08-19 18:31:37,090 basehttp 124 "OPTIONS /users/ HTTP/1.1" 200 0
INFO 2018-08-19 18:31:37,117 basehttp 124 "GET /usernames/qwerty/count/ HTTP/1.1" 200 32
INFO 2018-08-19 18:31:37,121 basehttp 124 "GET /mobiles/13123456789/count/ HTTP/1.1" 200 34
WARNING 2018-08-19 18:31:37,163 basehttp 124 "POST /users/ HTTP/1.1" 400 43
INFO 2018-08-19 18:32:47,403 basehttp 124 "GET /mobiles/13123456789/count/ HTTP/1.1" 200 34
INFO 2018-08-19 18:32:47,471 basehttp 124 "GET /sms_code/13123456789/ HTTP/1.1" 200 16
INFO 2018-08-19 18:33:04,240 basehttp 124 "OPTIONS /users/ HTTP/1.1" 200 0
INFO 2018-08-19 18:33:04,250 basehttp 124 "GET /usernames/qwerty/count/ HTTP/1.1" 200 32
INFO 2018-08-19 18:33:04,268 basehttp 124 "GET /mobiles/13123456789/count/ HTTP/1.1" 200 34
INFO 2018-08-19 18:33:04,358 basehttp 124 "POST /users/ HTTP/1.1" 201 51
WARNING 2018-08-21 15:06:21,725 base 152 Not Found: /
WARNING 2018-08-21 15:06:21,729 basehttp 124 "GET / HTTP/1.1" 404 2655
WARNING 2018-08-21 15:06:21,799 base 152 Not Found: /favicon.ico
WARNING 2018-08-21 15:06:21,812 basehttp 124 "GET /favicon.ico HTTP/1.1" 404 2706
INFO 2018-08-21 15:06:26,767 basehttp 124 "GET /users HTTP/1.1" 301 0
INFO 2018-08-21 15:06:26,918 basehttp 124 "GET /static/rest_framework/css/bootstrap-tweaks.css HTTP/1.1" 304 0
INFO 2018-08-21 15:06:26,919 basehttp 124 "GET /static/rest_framework/css/bootstrap.min.css HTTP/1.1" 304 0
WARNING 2018-08-21 15:06:26,922 basehttp 124 "GET /users/ HTTP/1.1" 405 8411
INFO 2018-08-21 15:06:26,925 basehttp 124 "GET /static/rest_framework/css/prettify.css HTTP/1.1" 304 0
INFO 2018-08-21 15:06:26,939 basehttp 124 "GET /static/rest_framework/css/default.css HTTP/1.1" 304 0
INFO 2018-08-21 15:06:26,951 basehttp 124 "GET /static/rest_framework/js/jquery-3.3.1.min.js HTTP/1.1" 304 0
INFO 2018-08-21 15:06:26,964 basehttp 124 "GET /static/rest_framework/js/ajax-form.js HTTP/1.1" 304 0
INFO 2018-08-21 15:06:26,974 basehttp 124 "GET /static/rest_framework/js/csrf.js HTTP/1.1" 304 0
INFO 2018-08-21 15:06:26,986 basehttp 124 "GET /static/rest_framework/js/bootstrap.min.js HTTP/1.1" 304 0
INFO 2018-08-21 15:06:26,994 basehttp 124 "GET /static/rest_framework/js/prettify-min.js HTTP/1.1" 304 0
INFO 2018-08-21 15:06:26,999 basehttp 124 "GET /static/rest_framework/js/default.js HTTP/1.1" 304 0
INFO 2018-08-21 15:06:27,337 basehttp 124 "GET /static/rest_framework/img/grid.png HTTP/1.1" 304 0
WARNING 2018-08-21 16:09:33,946 base 152 Not Found: /
WARNING 2018-08-21 16:09:33,950 basehttp 124 "GET / HTTP/1.1" 404 2819
WARNING 2018-08-21 16:09:38,633 base 152 Not Found: /user
WARNING 2018-08-21 16:09:38,634 basehttp 124 "GET /user HTTP/1.1" 404 2849
WARNING 2018-08-21 16:09:45,640 base 152 Not Found: /user
WARNING 2018-08-21 16:09:45,642 basehttp 124 "GET /user HTTP/1.1" 404 2849
INFO 2018-08-21 16:09:53,455 basehttp 124 "GET /users HTTP/1.1" 301 0
WARNING 2018-08-21 16:09:53,513 basehttp 124 "GET /users/ HTTP/1.1" 405 8411
WARNING 2018-08-21 16:11:10,759 base 152 Not Found: /au
WARNING 2018-08-21 16:11:10,775 basehttp 124 "GET /au HTTP/1.1" 404 2843
INFO 2018-08-21 16:11:44,669 basehttp 124 "GET /authorizations HTTP/1.1" 301 0
WARNING 2018-08-21 16:11:44,715 basehttp 124 "GET /authorizations/ HTTP/1.1" 405 7589
WARNING 2018-08-21 16:12:04,315 basehttp 124 "POST /authorizations/ HTTP/1.1" 400 7631
WARNING 2018-08-21 16:14:30,317 basehttp 124 "GET /users/ HTTP/1.1" 405 8411
WARNING 2018-08-21 16:14:36,177 base 152 Not Found: /
WARNING 2018-08-21 16:14:36,178 basehttp 124 "GET / HTTP/1.1" 404 2820
INFO 2018-08-21 16:14:45,599 basehttp 124 "GET /sms_code/17695566006 HTTP/1.1" 301 0
INFO 2018-08-21 16:14:45,704 basehttp 124 "GET /sms_code/17695566006/ HTTP/1.1" 200 5170
WARNING 2018-08-21 16:15:56,632 basehttp 124 "POST /users/ HTTP/1.1" 400 8740
INFO 2018-08-21 16:16:57,444 basehttp 124 "GET /sms_code/17695566006/ HTTP/1.1" 200 5170
ERROR 2018-08-21 16:17:09,439 exception 135 Internal Server Error: /users/
Traceback (most recent call last):
  File "/home/python/.virtualenvs/django_cp4/lib/python3.5/site-packages/django/core/handlers/exception.py", line 41, in inner
    response = get_response(request)
  File "/home/python/.virtualenvs/django_cp4/lib/python3.5/site-packages/django/core/handlers/base.py", line 187, in _get_response
    response = self.process_exception_by_middleware(e, request)
  File "/home/python/.virtualenvs/django_cp4/lib/python3.5/site-packages/django/core/handlers/base.py", line 185, in _get_response
    response = wrapped_callback(request, *callback_args, **callback_kwargs)
  File "/home/python/.virtualenvs/django_cp4/lib/python3.5/site-packages/django/views/decorators/csrf.py", line 58, in wrapped_view
    return view_func(*args, **kwargs)
  File "/home/python/.virtualenvs/django_cp4/lib/python3.5/site-packages/django/views/generic/base.py", line 68, in view
    return self.dispatch(request, *args, **kwargs)
  File "/home/python/.virtualenvs/django_cp4/lib/python3.5/site-packages/rest_framework/views.py", line 483, in dispatch
    response = self.handle_exception(exc)
  File "/home/python/.virtualenvs/django_cp4/lib/python3.5/site-packages/rest_framework/views.py", line 443, in handle_exception
    self.raise_uncaught_exception(exc)
  File "/home/python/.virtualenvs/django_cp4/lib/python3.5/site-packages/rest_framework/views.py", line 480, in dispatch
    response = handler(request, *args, **kwargs)
  File "/home/python/.virtualenvs/django_cp4/lib/python3.5/site-packages/rest_framework/generics.py", line 192, in post
    return self.create(request, *args, **kwargs)
  File "/home/python/.virtualenvs/django_cp4/lib/python3.5/site-packages/rest_framework/mixins.py", line 21, in create
    self.perform_create(serializer)
  File "/home/python/.virtualenvs/django_cp4/lib/python3.5/site-packages/rest_framework/mixins.py", line 26, in perform_create
    serializer.save()
  File "/home/python/.virtualenvs/django_cp4/lib/python3.5/site-packages/rest_framework/serializers.py", line 214, in save
    self.instance = self.create(validated_data)
  File "/home/python/Desktop/Django_1/meiduo_api/apps/users/serializers.py", line 110, in create
    jwt_payload_handler = api_settings.JWT_PAYLOAD_HANDLER
  File "/home/python/.virtualenvs/django_cp4/lib/python3.5/site-packages/rest_framework/settings.py", line 216, in __getattr__
    raise AttributeError("Invalid API setting: '%s'" % attr)
AttributeError: Invalid API setting: 'JWT_PAYLOAD_HANDLER'
ERROR 2018-08-21 16:17:09,553 basehttp 124 "POST /users/ HTTP/1.1" 500 121032
INFO 2018-08-21 16:21:26,847 basehttp 124 "GET /sms_code/17695566006/ HTTP/1.1" 200 5170
INFO 2018-08-21 16:21:26,890 basehttp 124 "GET /static/rest_framework/css/bootstrap.min.css HTTP/1.1" 304 0
INFO 2018-08-21 16:21:26,893 basehttp 124 "GET /static/rest_framework/css/bootstrap-tweaks.css HTTP/1.1" 304 0
INFO 2018-08-21 16:21:26,906 basehttp 124 "GET /static/rest_framework/css/prettify.css HTTP/1.1" 304 0
INFO 2018-08-21 16:21:26,920 basehttp 124 "GET /static/rest_framework/css/default.css HTTP/1.1" 304 0
INFO 2018-08-21 16:21:26,929 basehttp 124 "GET /static/rest_framework/js/ajax-form.js HTTP/1.1" 304 0
INFO 2018-08-21 16:21:26,930 basehttp 124 "GET /static/rest_framework/js/jquery-3.3.1.min.js HTTP/1.1" 304 0
INFO 2018-08-21 16:21:26,938 basehttp 124 "GET /static/rest_framework/js/csrf.js HTTP/1.1" 304 0
INFO 2018-08-21 16:21:26,943 basehttp 124 "GET /static/rest_framework/js/bootstrap.min.js HTTP/1.1" 304 0
INFO 2018-08-21 16:21:26,947 basehttp 124 "GET /static/rest_framework/js/prettify-min.js HTTP/1.1" 304 0
INFO 2018-08-21 16:21:26,954 basehttp 124 "GET /static/rest_framework/js/default.js HTTP/1.1" 304 0
WARNING 2018-08-21 16:21:43,076 basehttp 124 "POST /users/ HTTP/1.1" 400 8544
WARNING 2018-08-21 16:22:11,190 basehttp 124 "GET /authorizations/ HTTP/1.1" 405 7589
INFO 2018-08-21 16:22:21,394 basehttp 124 "POST /authorizations/ HTTP/1.1" 200 7704
WARNING 2018-08-21 16:22:34,429 basehttp 124 "POST /authorizations/ HTTP/1.1" 400 7639
WARNING 2018-08-21 16:23:00,168 basehttp 124 "POST /authorizations/ HTTP/1.1" 400 7639
WARNING 2018-08-21 16:23:51,779 basehttp 124 "POST /authorizations/ HTTP/1.1" 400 7639
WARNING 2018-08-21 16:26:30,522 basehttp 124 "POST /authorizations/ HTTP/1.1" 400 7639
WARNING 2018-08-21 16:28:57,612 basehttp 124 "GET /authorizations/ HTTP/1.1" 405 7589
WARNING 2018-08-21 16:29:13,736 basehttp 124 "POST /authorizations/ HTTP/1.1" 400 7639
INFO 2018-08-21 16:29:34,648 basehttp 124 "POST /authorizations/ HTTP/1.1" 200 7704
WARNING 2018-08-21 16:31:53,490 basehttp 124 "POST /authorizations/ HTTP/1.1" 400 7639
INFO 2018-08-21 16:32:07,639 basehttp 124 "POST /authorizations/ HTTP/1.1" 200 7704
WARNING 2018-08-21 16:33:18,140 basehttp 124 "POST /authorizations/ HTTP/1.1" 400 7639
INFO 2018-08-21 16:33:28,388 basehttp 124 "POST /authorizations/ HTTP/1.1" 200 7778
WARNING 2018-08-21 16:33:43,078 basehttp 124 "POST /authorizations/ HTTP/1.1" 400 7639
WARNING 2018-08-21 16:34:25,342 basehttp 124 "POST /authorizations/ HTTP/1.1" 400 7639
INFO 2018-08-21 16:36:00,964 basehttp 124 "POST /authorizations/ HTTP/1.1" 200 7778
WARNING 2018-08-24 14:49:51,897 base 152 Not Found: /oauth/qq/authorization/
WARNING 2018-08-24 14:49:51,902 basehttp 124 "GET /oauth/qq/authorization/?next=/ HTTP/1.1" 404 3238
WARNING 2018-08-24 14:49:54,086 base 152 Not Found: /oauth/qq/authorization/
WARNING 2018-08-24 14:49:54,087 basehttp 124 "GET /oauth/qq/authorization/?next=/ HTTP/1.1" 404 3238
WARNING 2018-08-24 14:49:54,826 base 152 Not Found: /oauth/qq/authorization/
WARNING 2018-08-24 14:49:54,828 basehttp 124 "GET /oauth/qq/authorization/?next=/ HTTP/1.1" 404 3238
WARNING 2018-08-24 14:49:55,673 base 152 Not Found: /oauth/qq/authorization/
WARNING 2018-08-24 14:49:55,675 basehttp 124 "GET /oauth/qq/authorization/?next=/ HTTP/1.1" 404 3238
WARNING 2018-08-24 14:49:55,893 base 152 Not Found: /oauth/qq/authorization/
WARNING 2018-08-24 14:49:55,897 basehttp 124 "GET /oauth/qq/authorization/?next=/ HTTP/1.1" 404 3238
WARNING 2018-08-24 14:49:56,076 base 152 Not Found: /oauth/qq/authorization/
WARNING 2018-08-24 14:49:56,077 basehttp 124 "GET /oauth/qq/authorization/?next=/ HTTP/1.1" 404 3238
WARNING 2018-08-24 14:50:05,132 base 152 Not Found: /oauth/qq/authorization/
WARNING 2018-08-24 14:50:05,135 basehttp 124 "GET /oauth/qq/authorization/?next=/ HTTP/1.1" 404 3238
WARNING 2018-08-24 14:51:09,349 base 152 Not Found: /oauth/qq/authorization/
WARNING 2018-08-24 14:51:09,351 basehttp 124 "GET /oauth/qq/authorization/?next=/ HTTP/1.1" 404 3238
WARNING 2018-08-24 14:51:17,484 base 152 Not Found: /oauth/qq/authorization/
WARNING 2018-08-24 14:51:17,487 basehttp 124 "GET /oauth/qq/authorization/?next=/ HTTP/1.1" 404 3238
WARNING 2018-08-24 14:51:19,306 base 152 Not Found: /oauth/qq/authorization/
WARNING 2018-08-24 14:51:19,308 basehttp 124 "GET /oauth/qq/authorization/?next=/ HTTP/1.1" 404 3238
WARNING 2018-08-24 14:52:34,132 base 152 Not Found: /oauth/qq/authorization/
WARNING 2018-08-24 14:52:34,133 basehttp 124 "GET /oauth/qq/authorization/?next=/ HTTP/1.1" 404 3238
INFO 2018-08-24 14:54:37,231 basehttp 124 "GET /oauth/qq/authorization/?next=/ HTTP/1.1" 200 195
INFO 2018-08-24 14:54:52,998 basehttp 124 "GET /oauth/qq/user/?code=772A8EA9D730AE5D09BF62B69D7275D1 HTTP/1.1" 200 190
INFO 2018-08-24 14:55:39,687 basehttp 124 "GET /sms_code/17695566006/ HTTP/1.1" 200 16
INFO 2018-08-24 14:55:49,310 basehttp 124 "OPTIONS /oauth/qq/user/ HTTP/1.1" 200 0
ERROR 2018-08-24 14:55:49,320 exception 135 Internal Server Error: /oauth/qq/user/
Traceback (most recent call last):
  File "/home/python/.virtualenvs/django_cp4/lib/python3.5/site-packages/django/core/handlers/exception.py", line 41, in inner
    response = get_response(request)
  File "/home/python/.virtualenvs/django_cp4/lib/python3.5/site-packages/django/core/handlers/base.py", line 187, in _get_response
    response = self.process_exception_by_middleware(e, request)
  File "/home/python/.virtualenvs/django_cp4/lib/python3.5/site-packages/django/core/handlers/base.py", line 185, in _get_response
    response = wrapped_callback(request, *callback_args, **callback_kwargs)
  File "/home/python/.virtualenvs/django_cp4/lib/python3.5/site-packages/django/views/decorators/csrf.py", line 58, in wrapped_view
    return view_func(*args, **kwargs)
  File "/home/python/.virtualenvs/django_cp4/lib/python3.5/site-packages/django/views/generic/base.py", line 68, in view
    return self.dispatch(request, *args, **kwargs)
  File "/home/python/.virtualenvs/django_cp4/lib/python3.5/site-packages/rest_framework/views.py", line 483, in dispatch
    response = self.handle_exception(exc)
  File "/home/python/.virtualenvs/django_cp4/lib/python3.5/site-packages/rest_framework/views.py", line 443, in handle_exception
    self.raise_uncaught_exception(exc)
  File "/home/python/.virtualenvs/django_cp4/lib/python3.5/site-packages/rest_framework/views.py", line 480, in dispatch
    response = handler(request, *args, **kwargs)
  File "/home/python/Desktop/Django_1/meiduo_api/apps/oauth/views.py", line 76, in post
    serializer.is_valid(raise_exception=True)
  File "/home/python/.virtualenvs/django_cp4/lib/python3.5/site-packages/rest_framework/serializers.py", line 236, in is_valid
    self._validated_data = self.run_validation(self.initial_data)
  File "/home/python/.virtualenvs/django_cp4/lib/python3.5/site-packages/rest_framework/serializers.py", line 437, in run_validation
    value = self.validate(value)
  File "/home/python/Desktop/Django_1/meiduo_api/apps/oauth/serializers.py", line 49, in validate
    redis_conn = get_redis_connection('verify_codes')
  File "/home/python/.virtualenvs/django_cp4/lib/python3.5/site-packages/django_redis/__init__.py", line 14, in get_redis_connection
    cache = caches[alias]
  File "/home/python/.virtualenvs/django_cp4/lib/python3.5/site-packages/django/core/cache/__init__.py", line 77, in __getitem__
    "Could not find config for '%s' in settings.CACHES" % alias
django.core.cache.backends.base.InvalidCacheBackendError: Could not find config for 'verify_codes' in settings.CACHES
ERROR 2018-08-24 14:55:49,412 basehttp 124 "POST /oauth/qq/user/ HTTP/1.1" 500 19123
ERROR 2018-08-24 14:56:47,284 utils 74 code=None msg=None
ERROR 2018-08-24 14:56:47,285 basehttp 124 "GET /oauth/qq/user/?code=772A8EA9D730AE5D09BF62B69D7275D1 HTTP/1.1" 503 28
INFO 2018-08-24 14:56:54,466 basehttp 124 "GET /oauth/qq/authorization/?next=/ HTTP/1.1" 200 195
INFO 2018-08-24 14:57:05,202 basehttp 124 "GET /oauth/qq/user/?code=1B41E4CBBF590D6E19D6B41488AF3C0E HTTP/1.1" 200 190
INFO 2018-08-24 14:57:31,097 basehttp 124 "GET /sms_code/18639183676/ HTTP/1.1" 200 16
INFO 2018-08-24 14:57:41,427 basehttp 124 "POST /oauth/qq/user/ HTTP/1.1" 200 218
INFO 2018-08-24 16:39:19,376 basehttp 124 "GET /usernames/hideto/count/ HTTP/1.1" 200 32
INFO 2018-08-24 16:39:30,535 basehttp 124 "GET /mobiles/17695566006/count/ HTTP/1.1" 200 34
INFO 2018-08-24 16:40:02,295 basehttp 124 "GET /mobiles/17695566006/count/ HTTP/1.1" 200 34
INFO 2018-08-24 16:40:02,345 basehttp 124 "GET /sms_code/17695566006/ HTTP/1.1" 200 16
WARNING 2018-08-24 16:40:12,292 basehttp 124 "GET /sms_code/17695566006/ HTTP/1.1" 400 37
INFO 2018-08-24 16:40:12,302 basehttp 124 "GET /mobiles/17695566006/count/ HTTP/1.1" 200 34
INFO 2018-08-24 16:40:29,373 basehttp 124 "GET /usernames/hideto/count/ HTTP/1.1" 200 32
INFO 2018-08-24 16:40:29,383 basehttp 124 "GET /mobiles/17695566006/count/ HTTP/1.1" 200 34
INFO 2018-08-24 16:40:29,393 basehttp 124 "OPTIONS /users/ HTTP/1.1" 200 0
INFO 2018-08-24 16:40:41,432 basehttp 124 "GET /usernames/hideto/count/ HTTP/1.1" 200 32
INFO 2018-08-24 16:40:41,437 basehttp 124 "OPTIONS /users/ HTTP/1.1" 200 0
INFO 2018-08-24 16:40:41,441 basehttp 124 "GET /mobiles/17695566006/count/ HTTP/1.1" 200 34
INFO 2018-08-24 16:41:10,752 basehttp 124 "GET /usernames/uchida/count/ HTTP/1.1" 200 32
INFO 2018-08-24 16:41:26,156 basehttp 124 "GET /mobiles/17695566006/count/ HTTP/1.1" 200 34
INFO 2018-08-24 16:41:34,318 basehttp 124 "GET /mobiles/17695566006/count/ HTTP/1.1" 200 34
INFO 2018-08-24 16:41:35,598 basehttp 124 "GET /mobiles/17695566006/count/ HTTP/1.1" 200 34
INFO 2018-08-24 16:41:35,613 basehttp 124 "GET /sms_code/17695566006/ HTTP/1.1" 200 16
INFO 2018-08-24 16:41:47,209 basehttp 124 "OPTIONS /users/ HTTP/1.1" 200 0
INFO 2018-08-24 16:41:47,221 basehttp 124 "GET /usernames/uchida/count/ HTTP/1.1" 200 32
INFO 2018-08-24 16:41:47,225 basehttp 124 "GET /mobiles/17695566006/count/ HTTP/1.1" 200 34
WARNING 2018-08-24 16:41:52,785 basehttp 124 "GET /users/ HTTP/1.1" 405 8411
INFO 2018-08-24 16:41:52,820 basehttp 124 "GET /static/rest_framework/css/bootstrap.min.css HTTP/1.1" 304 0
INFO 2018-08-24 16:41:52,823 basehttp 124 "GET /static/rest_framework/css/bootstrap-tweaks.css HTTP/1.1" 304 0
INFO 2018-08-24 16:41:52,830 basehttp 124 "GET /static/rest_framework/css/prettify.css HTTP/1.1" 304 0
INFO 2018-08-24 16:41:52,830 basehttp 124 "GET /static/rest_framework/css/default.css HTTP/1.1" 304 0
INFO 2018-08-24 16:41:52,832 basehttp 124 "GET /static/rest_framework/js/jquery-3.3.1.min.js HTTP/1.1" 304 0
INFO 2018-08-24 16:41:52,832 basehttp 124 "GET /static/rest_framework/js/ajax-form.js HTTP/1.1" 304 0
INFO 2018-08-24 16:41:52,837 basehttp 124 "GET /static/rest_framework/js/csrf.js HTTP/1.1" 304 0
INFO 2018-08-24 16:41:52,844 basehttp 124 "GET /static/rest_framework/js/bootstrap.min.js HTTP/1.1" 304 0
INFO 2018-08-24 16:41:52,854 basehttp 124 "GET /static/rest_framework/js/prettify-min.js HTTP/1.1" 304 0
INFO 2018-08-24 16:41:52,855 basehttp 124 "GET /static/rest_framework/js/default.js HTTP/1.1" 304 0
INFO 2018-08-24 16:41:52,908 basehttp 124 "GET /static/rest_framework/img/grid.png HTTP/1.1" 304 0
WARNING 2018-08-24 16:41:53,101 base 152 Not Found: /favicon.ico
WARNING 2018-08-24 16:41:53,102 basehttp 124 "GET /favicon.ico HTTP/1.1" 404 3134
ERROR 2018-08-24 16:42:33,956 exception 135 Internal Server Error: /users/
Traceback (most recent call last):
  File "/home/python/.virtualenvs/django_cp4/lib/python3.5/site-packages/django/core/handlers/exception.py", line 41, in inner
    response = get_response(request)
  File "/home/python/.virtualenvs/django_cp4/lib/python3.5/site-packages/django/core/handlers/base.py", line 187, in _get_response
    response = self.process_exception_by_middleware(e, request)
  File "/home/python/.virtualenvs/django_cp4/lib/python3.5/site-packages/django/core/handlers/base.py", line 185, in _get_response
    response = wrapped_callback(request, *callback_args, **callback_kwargs)
  File "/home/python/.virtualenvs/django_cp4/lib/python3.5/site-packages/django/views/decorators/csrf.py", line 58, in wrapped_view
    return view_func(*args, **kwargs)
  File "/home/python/.virtualenvs/django_cp4/lib/python3.5/site-packages/django/views/generic/base.py", line 68, in view
    return self.dispatch(request, *args, **kwargs)
  File "/home/python/.virtualenvs/django_cp4/lib/python3.5/site-packages/rest_framework/views.py", line 483, in dispatch
    response = self.handle_exception(exc)
  File "/home/python/.virtualenvs/django_cp4/lib/python3.5/site-packages/rest_framework/views.py", line 443, in handle_exception
    self.raise_uncaught_exception(exc)
  File "/home/python/.virtualenvs/django_cp4/lib/python3.5/site-packages/rest_framework/views.py", line 480, in dispatch
    response = handler(request, *args, **kwargs)
  File "/home/python/.virtualenvs/django_cp4/lib/python3.5/site-packages/rest_framework/generics.py", line 192, in post
    return self.create(request, *args, **kwargs)
  File "/home/python/.virtualenvs/django_cp4/lib/python3.5/site-packages/rest_framework/mixins.py", line 21, in create
    self.perform_create(serializer)
  File "/home/python/.virtualenvs/django_cp4/lib/python3.5/site-packages/rest_framework/mixins.py", line 26, in perform_create
    serializer.save()
  File "/home/python/.virtualenvs/django_cp4/lib/python3.5/site-packages/rest_framework/serializers.py", line 214, in save
    self.instance = self.create(validated_data)
  File "/home/python/Desktop/Django_1/meiduo_api/apps/users/serializers.py", line 110, in create
    jwt_payload_handler = api_settings.JWT_PAYLOAD_HANDLER
  File "/home/python/.virtualenvs/django_cp4/lib/python3.5/site-packages/rest_framework/settings.py", line 216, in __getattr__
    raise AttributeError("Invalid API setting: '%s'" % attr)
AttributeError: Invalid API setting: 'JWT_PAYLOAD_HANDLER'
ERROR 2018-08-24 16:42:34,060 basehttp 124 "POST /users/ HTTP/1.1" 500 123285
INFO 2018-08-24 16:46:01,308 basehttp 124 "GET /oauth/qq/authorization/?next=/ HTTP/1.1" 200 195
INFO 2018-08-24 16:46:03,386 basehttp 124 "GET /oauth/qq/authorization/?next=/ HTTP/1.1" 200 195
INFO 2018-08-24 16:49:22,170 basehttp 124 "GET /oauth/qq/authorization/?next=/ HTTP/1.1" 200 195
INFO 2018-08-24 16:49:34,355 basehttp 124 "GET /oauth/qq/authorization/?next=/ HTTP/1.1" 200 195
INFO 2018-08-24 16:49:47,021 basehttp 124 "GET /oauth/qq/user/?code=EA789327645DA7492984217C2B0F2212 HTTP/1.1" 200 190
INFO 2018-08-24 16:50:00,174 basehttp 124 "GET /sms_code/17695566006/ HTTP/1.1" 200 16
INFO 2018-08-24 16:50:28,868 basehttp 124 "OPTIONS /oauth/qq/user/ HTTP/1.1" 200 0
INFO 2018-08-24 16:50:29,150 basehttp 124 "POST /oauth/qq/user/ HTTP/1.1" 200 207
INFO 2018-08-24 16:50:40,274 basehttp 124 "OPTIONS /user/ HTTP/1.1" 200 0
WARNING 2018-08-24 16:50:40,333 base 152 Not Found: /user/
WARNING 2018-08-24 16:50:40,334 basehttp 124 "GET /user/ HTTP/1.1" 404 3116
WARNING 2018-08-24 16:50:43,394 base 152 Not Found: /user/
WARNING 2018-08-24 16:50:43,395 basehttp 124 "GET /user/ HTTP/1.1" 404 3116
WARNING 2018-08-24 16:51:03,738 base 152 Not Found: /user/
WARNING 2018-08-24 16:51:03,738 basehttp 124 "GET /user/ HTTP/1.1" 404 3116
WARNING 2018-08-24 16:51:05,731 base 152 Not Found: /user/
WARNING 2018-08-24 16:51:05,732 basehttp 124 "GET /user/ HTTP/1.1" 404 3116
WARNING 2018-08-24 16:51:09,472 base 152 Not Found: /user/
WARNING 2018-08-24 16:51:09,472 basehttp 124 "GET /user/ HTTP/1.1" 404 3116
INFO 2018-08-24 16:51:51,455 basehttp 124 "OPTIONS /user/ HTTP/1.1" 200 0
WARNING 2018-08-24 16:51:51,514 base 152 Not Found: /user/
WARNING 2018-08-24 16:51:51,514 basehttp 124 "GET /user/ HTTP/1.1" 404 3116
INFO 2018-08-24 16:52:47,942 basehttp 124 "GET /oauth/qq/authorization/?next=/ HTTP/1.1" 200 195
INFO 2018-08-24 16:53:03,113 basehttp 124 "GET /oauth/qq/user/?code=E1CF17D3CBE0F684D6268BFF430374B1 HTTP/1.1" 200 207
WARNING 2018-08-24 16:53:07,701 base 152 Not Found: /user/
WARNING 2018-08-24 16:53:07,702 basehttp 124 "GET /user/ HTTP/1.1" 404 3116
WARNING 2018-08-24 16:53:09,519 base 152 Not Found: /user/
WARNING 2018-08-24 16:53:09,520 basehttp 124 "GET /user/ HTTP/1.1" 404 3116
WARNING 2018-08-24 16:53:11,799 base 152 Not Found: /areas/
WARNING 2018-08-24 16:53:11,802 basehttp 124 "GET /areas/ HTTP/1.1" 404 3119
INFO 2018-08-24 16:53:11,803 basehttp 124 "OPTIONS /addresses/ HTTP/1.1" 200 0
WARNING 2018-08-24 16:53:11,839 base 152 Not Found: /addresses/
WARNING 2018-08-24 16:53:11,839 basehttp 124 "GET /addresses/ HTTP/1.1" 404 3131
WARNING 2018-08-24 16:53:18,973 base 152 Not Found: /user/
WARNING 2018-08-24 16:53:18,974 basehttp 124 "GET /user/ HTTP/1.1" 404 3116
WARNING 2018-08-24 16:53:21,190 base 152 Not Found: /user/
WARNING 2018-08-24 16:53:21,191 basehttp 124 "GET /user/ HTTP/1.1" 404 3116
INFO 2018-08-24 16:53:31,426 basehttp 124 "OPTIONS /emails/ HTTP/1.1" 200 0
ERROR 2018-08-24 16:53:31,459 exception 135 Internal Server Error: /emails/
Traceback (most recent call last):
  File "/home/python/.virtualenvs/django_cp4/lib/python3.5/site-packages/django/core/handlers/exception.py", line 41, in inner
    response = get_response(request)
  File "/home/python/.virtualenvs/django_cp4/lib/python3.5/site-packages/django/core/handlers/base.py", line 187, in _get_response
    response = self.process_exception_by_middleware(e, request)
  File "/home/python/.virtualenvs/django_cp4/lib/python3.5/site-packages/django/core/handlers/base.py", line 185, in _get_response
    response = wrapped_callback(request, *callback_args, **callback_kwargs)
  File "/home/python/.virtualenvs/django_cp4/lib/python3.5/site-packages/django/views/decorators/csrf.py", line 58, in wrapped_view
    return view_func(*args, **kwargs)
  File "/home/python/.virtualenvs/django_cp4/lib/python3.5/site-packages/django/views/generic/base.py", line 68, in view
    return self.dispatch(request, *args, **kwargs)
  File "/home/python/.virtualenvs/django_cp4/lib/python3.5/site-packages/rest_framework/views.py", line 483, in dispatch
    response = self.handle_exception(exc)
  File "/home/python/.virtualenvs/django_cp4/lib/python3.5/site-packages/rest_framework/views.py", line 443, in handle_exception
    self.raise_uncaught_exception(exc)
  File "/home/python/.virtualenvs/django_cp4/lib/python3.5/site-packages/rest_framework/views.py", line 480, in dispatch
    response = handler(request, *args, **kwargs)
  File "/home/python/.virtualenvs/django_cp4/lib/python3.5/site-packages/rest_framework/generics.py", line 228, in put
    return self.update(request, *args, **kwargs)
  File "/home/python/.virtualenvs/django_cp4/lib/python3.5/site-packages/rest_framework/mixins.py", line 70, in update
    self.perform_update(serializer)
  File "/home/python/.virtualenvs/django_cp4/lib/python3.5/site-packages/rest_framework/mixins.py", line 80, in perform_update
    serializer.save()
  File "/home/python/.virtualenvs/django_cp4/lib/python3.5/site-packages/rest_framework/serializers.py", line 209, in save
    self.instance = self.update(self.instance, validated_data)
  File "/home/python/Desktop/Django_1/meiduo_api/apps/users/serializers.py", line 134, in update
    email = validated_data['email']
KeyError: 'email'
ERROR 2018-08-24 16:53:31,520 basehttp 124 "PUT /emails/ HTTP/1.1" 500 18832
WARNING 2018-08-24 16:55:25,435 base 152 Not Found: /user/
WARNING 2018-08-24 16:55:25,438 basehttp 124 "GET /user/ HTTP/1.1" 404 3116
WARNING 2018-08-24 16:55:27,168 base 152 Not Found: /user/
WARNING 2018-08-24 16:55:27,168 basehttp 124 "GET /user/ HTTP/1.1" 404 3116
INFO 2018-08-24 16:55:30,180 basehttp 124 "GET /oauth/qq/authorization/?next=/ HTTP/1.1" 200 195
INFO 2018-08-24 16:55:39,927 basehttp 124 "GET /oauth/qq/user/?code=FC668930AB8964BC73ABDA9F508D3E4A HTTP/1.1" 200 207
WARNING 2018-08-24 16:55:42,087 base 152 Not Found: /user/
WARNING 2018-08-24 16:55:42,089 basehttp 124 "GET /user/ HTTP/1.1" 404 3116
INFO 2018-08-24 16:56:29,095 basehttp 124 "GET /user/ HTTP/1.1" 200 83
INFO 2018-08-24 16:56:29,117 basehttp 124 "OPTIONS /browse_histories/ HTTP/1.1" 200 0
WARNING 2018-08-24 16:56:29,133 base 152 Not Found: /browse_histories/
WARNING 2018-08-24 16:56:29,135 basehttp 124 "GET /browse_histories/ HTTP/1.1" 404 3307
ERROR 2018-08-24 16:56:47,084 exception 135 Internal Server Error: /emails/
Traceback (most recent call last):
  File "/home/python/.virtualenvs/django_cp4/lib/python3.5/site-packages/django/core/handlers/exception.py", line 41, in inner
    response = get_response(request)
  File "/home/python/.virtualenvs/django_cp4/lib/python3.5/site-packages/django/core/handlers/base.py", line 187, in _get_response
    response = self.process_exception_by_middleware(e, request)
  File "/home/python/.virtualenvs/django_cp4/lib/python3.5/site-packages/django/core/handlers/base.py", line 185, in _get_response
    response = wrapped_callback(request, *callback_args, **callback_kwargs)
  File "/home/python/.virtualenvs/django_cp4/lib/python3.5/site-packages/django/views/decorators/csrf.py", line 58, in wrapped_view
    return view_func(*args, **kwargs)
  File "/home/python/.virtualenvs/django_cp4/lib/python3.5/site-packages/django/views/generic/base.py", line 68, in view
    return self.dispatch(request, *args, **kwargs)
  File "/home/python/.virtualenvs/django_cp4/lib/python3.5/site-packages/rest_framework/views.py", line 483, in dispatch
    response = self.handle_exception(exc)
  File "/home/python/.virtualenvs/django_cp4/lib/python3.5/site-packages/rest_framework/views.py", line 443, in handle_exception
    self.raise_uncaught_exception(exc)
  File "/home/python/.virtualenvs/django_cp4/lib/python3.5/site-packages/rest_framework/views.py", line 480, in dispatch
    response = handler(request, *args, **kwargs)
  File "/home/python/.virtualenvs/django_cp4/lib/python3.5/site-packages/rest_framework/generics.py", line 228, in put
    return self.update(request, *args, **kwargs)
  File "/home/python/.virtualenvs/django_cp4/lib/python3.5/site-packages/rest_framework/mixins.py", line 70, in update
    self.perform_update(serializer)
  File "/home/python/.virtualenvs/django_cp4/lib/python3.5/site-packages/rest_framework/mixins.py", line 80, in perform_update
    serializer.save()
  File "/home/python/.virtualenvs/django_cp4/lib/python3.5/site-packages/rest_framework/serializers.py", line 209, in save
    self.instance = self.update(self.instance, validated_data)
  File "/home/python/Desktop/Django_1/meiduo_api/apps/users/serializers.py", line 134, in update
    instance.email = validated_data['email']
KeyError: 'email'
ERROR 2018-08-24 16:56:47,117 basehttp 124 "PUT /emails/ HTTP/1.1" 500 18841
ERROR 2018-08-24 16:57:54,083 exception 135 Internal Server Error: /emails/
Traceback (most recent call last):
  File "/home/python/.virtualenvs/django_cp4/lib/python3.5/site-packages/django/core/handlers/exception.py", line 41, in inner
    response = get_response(request)
  File "/home/python/.virtualenvs/django_cp4/lib/python3.5/site-packages/django/core/handlers/base.py", line 187, in _get_response
    response = self.process_exception_by_middleware(e, request)
  File "/home/python/.virtualenvs/django_cp4/lib/python3.5/site-packages/django/core/handlers/base.py", line 185, in _get_response
    response = wrapped_callback(request, *callback_args, **callback_kwargs)
  File "/home/python/.virtualenvs/django_cp4/lib/python3.5/site-packages/django/views/decorators/csrf.py", line 58, in wrapped_view
    return view_func(*args, **kwargs)
  File "/home/python/.virtualenvs/django_cp4/lib/python3.5/site-packages/django/views/generic/base.py", line 68, in view
    return self.dispatch(request, *args, **kwargs)
  File "/home/python/.virtualenvs/django_cp4/lib/python3.5/site-packages/rest_framework/views.py", line 483, in dispatch
    response = self.handle_exception(exc)
  File "/home/python/.virtualenvs/django_cp4/lib/python3.5/site-packages/rest_framework/views.py", line 443, in handle_exception
    self.raise_uncaught_exception(exc)
  File "/home/python/.virtualenvs/django_cp4/lib/python3.5/site-packages/rest_framework/views.py", line 480, in dispatch
    response = handler(request, *args, **kwargs)
  File "/home/python/.virtualenvs/django_cp4/lib/python3.5/site-packages/rest_framework/generics.py", line 228, in put
    return self.update(request, *args, **kwargs)
  File "/home/python/.virtualenvs/django_cp4/lib/python3.5/site-packages/rest_framework/mixins.py", line 70, in update
    self.perform_update(serializer)
  File "/home/python/.virtualenvs/django_cp4/lib/python3.5/site-packages/rest_framework/mixins.py", line 80, in perform_update
    serializer.save()
  File "/home/python/.virtualenvs/django_cp4/lib/python3.5/site-packages/rest_framework/serializers.py", line 209, in save
    self.instance = self.update(self.instance, validated_data)
  File "/home/python/Desktop/Django_1/meiduo_api/apps/users/serializers.py", line 135, in update
    email = validated_data['email']
KeyError: 'email'
ERROR 2018-08-24 16:57:54,107 basehttp 124 "PUT /emails/ HTTP/1.1" 500 18832
ERROR 2018-08-24 16:58:19,276 exception 135 Internal Server Error: /emails/
Traceback (most recent call last):
  File "/home/python/.virtualenvs/django_cp4/lib/python3.5/site-packages/django/core/handlers/exception.py", line 41, in inner
    response = get_response(request)
  File "/home/python/.virtualenvs/django_cp4/lib/python3.5/site-packages/django/core/handlers/base.py", line 187, in _get_response
    response = self.process_exception_by_middleware(e, request)
  File "/home/python/.virtualenvs/django_cp4/lib/python3.5/site-packages/django/core/handlers/base.py", line 185, in _get_response
    response = wrapped_callback(request, *callback_args, **callback_kwargs)
  File "/home/python/.virtualenvs/django_cp4/lib/python3.5/site-packages/django/views/decorators/csrf.py", line 58, in wrapped_view
    return view_func(*args, **kwargs)
  File "/home/python/.virtualenvs/django_cp4/lib/python3.5/site-packages/django/views/generic/base.py", line 68, in view
    return self.dispatch(request, *args, **kwargs)
  File "/home/python/.virtualenvs/django_cp4/lib/python3.5/site-packages/rest_framework/views.py", line 483, in dispatch
    response = self.handle_exception(exc)
  File "/home/python/.virtualenvs/django_cp4/lib/python3.5/site-packages/rest_framework/views.py", line 443, in handle_exception
    self.raise_uncaught_exception(exc)
  File "/home/python/.virtualenvs/django_cp4/lib/python3.5/site-packages/rest_framework/views.py", line 480, in dispatch
    response = handler(request, *args, **kwargs)
  File "/home/python/.virtualenvs/django_cp4/lib/python3.5/site-packages/rest_framework/generics.py", line 228, in put
    return self.update(request, *args, **kwargs)
  File "/home/python/.virtualenvs/django_cp4/lib/python3.5/site-packages/rest_framework/mixins.py", line 69, in update
    serializer.is_valid(raise_exception=True)
  File "/home/python/.virtualenvs/django_cp4/lib/python3.5/site-packages/rest_framework/serializers.py", line 236, in is_valid
    self._validated_data = self.run_validation(self.initial_data)
  File "/home/python/.virtualenvs/django_cp4/lib/python3.5/site-packages/rest_framework/serializers.py", line 434, in run_validation
    value = self.to_internal_value(data)
  File "/home/python/.virtualenvs/django_cp4/lib/python3.5/site-packages/rest_framework/serializers.py", line 482, in to_internal_value
    fields = self._writable_fields
  File "/home/python/.virtualenvs/django_cp4/lib/python3.5/site-packages/django/utils/functional.py", line 35, in __get__
    res = instance.__dict__[self.name] = self.func(instance)
  File "/home/python/.virtualenvs/django_cp4/lib/python3.5/site-packages/rest_framework/serializers.py", line 370, in _writable_fields
    field for field in self.fields.values() if not field.read_only
  File "/home/python/.virtualenvs/django_cp4/lib/python3.5/site-packages/rest_framework/serializers.py", line 363, in fields
    for key, value in self.get_fields().items():
  File "/home/python/.virtualenvs/django_cp4/lib/python3.5/site-packages/rest_framework/serializers.py", line 1054, in get_fields
    fields[field_name] = field_class(**field_kwargs)
  File "/home/python/.virtualenvs/django_cp4/lib/python3.5/site-packages/rest_framework/fields.py", line 797, in __init__
    super(EmailField, self).__init__(**kwargs)
  File "/home/python/.virtualenvs/django_cp4/lib/python3.5/site-packages/rest_framework/fields.py", line 754, in __init__
    super(CharField, self).__init__(**kwargs)
TypeError: __init__() got an unexpected keyword argument 'require'
ERROR 2018-08-24 16:58:19,308 basehttp 124 "PUT /emails/ HTTP/1.1" 500 20099
ERROR 2018-08-24 16:59:42,755 exception 135 Internal Server Error: /emails/
Traceback (most recent call last):
  File "/home/python/.virtualenvs/django_cp4/lib/python3.5/site-packages/django/core/handlers/exception.py", line 41, in inner
    response = get_response(request)
  File "/home/python/.virtualenvs/django_cp4/lib/python3.5/site-packages/django/core/handlers/base.py", line 187, in _get_response
    response = self.process_exception_by_middleware(e, request)
  File "/home/python/.virtualenvs/django_cp4/lib/python3.5/site-packages/django/core/handlers/base.py", line 185, in _get_response
    response = wrapped_callback(request, *callback_args, **callback_kwargs)
  File "/home/python/.virtualenvs/django_cp4/lib/python3.5/site-packages/django/views/decorators/csrf.py", line 58, in wrapped_view
    return view_func(*args, **kwargs)
  File "/home/python/.virtualenvs/django_cp4/lib/python3.5/site-packages/django/views/generic/base.py", line 68, in view
    return self.dispatch(request, *args, **kwargs)
  File "/home/python/.virtualenvs/django_cp4/lib/python3.5/site-packages/rest_framework/views.py", line 483, in dispatch
    response = self.handle_exception(exc)
  File "/home/python/.virtualenvs/django_cp4/lib/python3.5/site-packages/rest_framework/views.py", line 443, in handle_exception
    self.raise_uncaught_exception(exc)
  File "/home/python/.virtualenvs/django_cp4/lib/python3.5/site-packages/rest_framework/views.py", line 480, in dispatch
    response = handler(request, *args, **kwargs)
  File "/home/python/.virtualenvs/django_cp4/lib/python3.5/site-packages/rest_framework/generics.py", line 228, in put
    return self.update(request, *args, **kwargs)
  File "/home/python/.virtualenvs/django_cp4/lib/python3.5/site-packages/rest_framework/mixins.py", line 69, in update
    serializer.is_valid(raise_exception=True)
  File "/home/python/.virtualenvs/django_cp4/lib/python3.5/site-packages/rest_framework/serializers.py", line 236, in is_valid
    self._validated_data = self.run_validation(self.initial_data)
  File "/home/python/.virtualenvs/django_cp4/lib/python3.5/site-packages/rest_framework/serializers.py", line 434, in run_validation
    value = self.to_internal_value(data)
  File "/home/python/.virtualenvs/django_cp4/lib/python3.5/site-packages/rest_framework/serializers.py", line 482, in to_internal_value
    fields = self._writable_fields
  File "/home/python/.virtualenvs/django_cp4/lib/python3.5/site-packages/django/utils/functional.py", line 35, in __get__
    res = instance.__dict__[self.name] = self.func(instance)
  File "/home/python/.virtualenvs/django_cp4/lib/python3.5/site-packages/rest_framework/serializers.py", line 370, in _writable_fields
    field for field in self.fields.values() if not field.read_only
  File "/home/python/.virtualenvs/django_cp4/lib/python3.5/site-packages/rest_framework/serializers.py", line 363, in fields
    for key, value in self.get_fields().items():
  File "/home/python/.virtualenvs/django_cp4/lib/python3.5/site-packages/rest_framework/serializers.py", line 1054, in get_fields
    fields[field_name] = field_class(**field_kwargs)
  File "/home/python/.virtualenvs/django_cp4/lib/python3.5/site-packages/rest_framework/fields.py", line 797, in __init__
    super(EmailField, self).__init__(**kwargs)
  File "/home/python/.virtualenvs/django_cp4/lib/python3.5/site-packages/rest_framework/fields.py", line 754, in __init__
    super(CharField, self).__init__(**kwargs)
TypeError: __init__() got an unexpected keyword argument 'require'
ERROR 2018-08-24 16:59:42,785 basehttp 124 "PUT /emails/ HTTP/1.1" 500 20099
INFO 2018-08-24 17:03:38,783 basehttp 124 "OPTIONS /emails/ HTTP/1.1" 200 0
INFO 2018-08-24 17:03:38,849 basehttp 124 "PUT /emails/ HTTP/1.1" 200 37
INFO 2018-08-24 19:17:19,624 basehttp 124 "GET /oauth/qq/authorization/?next=/ HTTP/1.1" 200 195
INFO 2018-08-24 19:17:22,503 basehttp 124 "GET /oauth/qq/authorization/?next=/ HTTP/1.1" 200 195
INFO 2018-08-24 19:17:44,392 basehttp 124 "GET /oauth/qq/authorization/?next=/ HTTP/1.1" 200 195
INFO 2018-08-24 19:17:47,704 basehttp 124 "OPTIONS /user/ HTTP/1.1" 200 0
ERROR 2018-08-24 19:17:47,741 exceptions 25 [<users.views.UserDetailView object at 0x7f8fc67a1f28>] (1146, "Table 'meiduo_demo.tb_users' doesn't exist")
ERROR 2018-08-24 19:17:47,741 basehttp 124 "GET /user/ HTTP/1.1" 507 35
INFO 2018-08-24 19:17:51,934 basehttp 124 "GET /oauth/qq/authorization/?next=/ HTTP/1.1" 200 195
ERROR 2018-08-24 19:18:06,226 exceptions 25 [<oauth.views.QQAuthUserView object at 0x7f8fc67a7f28>] (1146, "Table 'meiduo_demo.tb_users' doesn't exist")
ERROR 2018-08-24 19:18:06,229 basehttp 124 "GET /oauth/qq/user/?code=3798996DBF2597E376D168B370000150 HTTP/1.1" 507 35
INFO 2018-08-24 19:18:41,534 basehttp 124 "GET /oauth/qq/authorization/?next=/ HTTP/1.1" 200 195
INFO 2018-08-24 19:18:51,472 basehttp 124 "GET /oauth/qq/user/?code=A280883D5F15DD30B9B9E53422FAEF44 HTTP/1.1" 200 231
INFO 2018-08-24 19:18:54,154 basehttp 124 "GET /user/ HTTP/1.1" 200 101
INFO 2018-08-24 19:18:54,227 basehttp 124 "OPTIONS /browse_histories/ HTTP/1.1" 200 0
WARNING 2018-08-24 19:18:54,240 base 152 Not Found: /browse_histories/
WARNING 2018-08-24 19:18:54,241 basehttp 124 "GET /browse_histories/ HTTP/1.1" 404 3478
INFO 2018-08-24 19:18:56,121 basehttp 124 "OPTIONS /emails/ HTTP/1.1" 200 0
INFO 2018-08-24 19:18:56,211 basehttp 124 "PUT /emails/ HTTP/1.1" 200 37
WARNING 2018-08-24 19:27:52,978 base 152 Not Found: /
WARNING 2018-08-24 19:27:52,979 basehttp 124 "GET / HTTP/1.1" 404 3403
WARNING 2018-08-24 19:27:53,074 base 152 Not Found: /favicon.ico
WARNING 2018-08-24 19:27:53,087 basehttp 124 "GET /favicon.ico HTTP/1.1" 404 3454
INFO 2018-08-24 19:28:02,939 basehttp 124 "GET /emails HTTP/1.1" 301 0
WARNING 2018-08-24 19:28:02,994 basehttp 124 "GET /emails/ HTTP/1.1" 401 3664
INFO 2018-08-24 19:28:03,002 basehttp 124 "GET /static/rest_framework/css/bootstrap-tweaks.css HTTP/1.1" 304 0
INFO 2018-08-24 19:28:03,003 basehttp 124 "GET /static/rest_framework/css/bootstrap.min.css HTTP/1.1" 304 0
INFO 2018-08-24 19:28:03,007 basehttp 124 "GET /static/rest_framework/css/prettify.css HTTP/1.1" 304 0
INFO 2018-08-24 19:28:03,009 basehttp 124 "GET /static/rest_framework/css/default.css HTTP/1.1" 304 0
INFO 2018-08-24 19:28:03,024 basehttp 124 "GET /static/rest_framework/js/jquery-3.3.1.min.js HTTP/1.1" 304 0
INFO 2018-08-24 19:28:03,025 basehttp 124 "GET /static/rest_framework/js/ajax-form.js HTTP/1.1" 304 0
INFO 2018-08-24 19:28:03,026 basehttp 124 "GET /static/rest_framework/js/csrf.js HTTP/1.1" 304 0
INFO 2018-08-24 19:28:03,027 basehttp 124 "GET /static/rest_framework/js/bootstrap.min.js HTTP/1.1" 304 0
INFO 2018-08-24 19:28:03,028 basehttp 124 "GET /static/rest_framework/js/prettify-min.js HTTP/1.1" 304 0
INFO 2018-08-24 19:28:03,031 basehttp 124 "GET /static/rest_framework/js/default.js HTTP/1.1" 304 0
INFO 2018-08-24 19:28:03,262 basehttp 124 "GET /static/rest_framework/img/grid.png HTTP/1.1" 304 0
WARNING 2018-08-24 19:28:22,189 base 152 Not Found: /oauth
WARNING 2018-08-24 19:28:22,190 basehttp 124 "GET /oauth HTTP/1.1" 404 3436
WARNING 2018-08-24 19:28:27,156 base 152 Not Found: /oauth/
WARNING 2018-08-24 19:28:27,157 basehttp 124 "GET /oauth/ HTTP/1.1" 404 3669
WARNING 2018-08-24 19:28:32,322 base 152 Not Found: /oauth/qq
WARNING 2018-08-24 19:28:32,326 basehttp 124 "GET /oauth/qq HTTP/1.1" 404 3675
INFO 2018-08-24 19:36:56,134 basehttp 124 "OPTIONS /user/ HTTP/1.1" 200 0
ERROR 2018-08-24 19:36:56,216 exceptions 25 [<users.views.UserDetailView object at 0x7efedbb9ca58>] (1146, "Table 'meiduo_demo.tb_users' doesn't exist")
ERROR 2018-08-24 19:36:56,216 basehttp 124 "GET /user/ HTTP/1.1" 507 35
ERROR 2018-08-24 19:36:58,486 exceptions 25 [<users.views.UserDetailView object at 0x7efeda0a00b8>] (1146, "Table 'meiduo_demo.tb_users' doesn't exist")
ERROR 2018-08-24 19:36:58,486 basehttp 124 "GET /user/ HTTP/1.1" 507 35
ERROR 2018-08-24 19:37:28,102 exception 135 Internal Server Error: /user/
Traceback (most recent call last):
  File "/home/python/.virtualenvs/django_cp4/lib/python3.5/site-packages/django/core/handlers/exception.py", line 41, in inner
    response = get_response(request)
  File "/home/python/.virtualenvs/django_cp4/lib/python3.5/site-packages/django/core/handlers/base.py", line 187, in _get_response
    response = self.process_exception_by_middleware(e, request)
  File "/home/python/.virtualenvs/django_cp4/lib/python3.5/site-packages/django/core/handlers/base.py", line 185, in _get_response
    response = wrapped_callback(request, *callback_args, **callback_kwargs)
  File "/home/python/.virtualenvs/django_cp4/lib/python3.5/site-packages/django/views/decorators/csrf.py", line 58, in wrapped_view
    return view_func(*args, **kwargs)
  File "/home/python/.virtualenvs/django_cp4/lib/python3.5/site-packages/django/views/generic/base.py", line 68, in view
    return self.dispatch(request, *args, **kwargs)
  File "/home/python/.virtualenvs/django_cp4/lib/python3.5/site-packages/rest_framework/views.py", line 483, in dispatch
    response = self.handle_exception(exc)
  File "/home/python/.virtualenvs/django_cp4/lib/python3.5/site-packages/rest_framework/views.py", line 443, in handle_exception
    self.raise_uncaught_exception(exc)
  File "/home/python/.virtualenvs/django_cp4/lib/python3.5/site-packages/rest_framework/views.py", line 480, in dispatch
    response = handler(request, *args, **kwargs)
  File "/home/python/.virtualenvs/django_cp4/lib/python3.5/site-packages/rest_framework/generics.py", line 210, in get
    return self.retrieve(request, *args, **kwargs)
  File "/home/python/.virtualenvs/django_cp4/lib/python3.5/site-packages/rest_framework/mixins.py", line 58, in retrieve
    return Response(serializer.data)
  File "/home/python/.virtualenvs/django_cp4/lib/python3.5/site-packages/rest_framework/serializers.py", line 560, in data
    ret = super(Serializer, self).data
  File "/home/python/.virtualenvs/django_cp4/lib/python3.5/site-packages/rest_framework/serializers.py", line 262, in data
    self._data = self.to_representation(self.instance)
  File "/home/python/.virtualenvs/django_cp4/lib/python3.5/site-packages/rest_framework/serializers.py", line 510, in to_representation
    fields = self._readable_fields
  File "/home/python/.virtualenvs/django_cp4/lib/python3.5/site-packages/django/utils/functional.py", line 35, in __get__
    res = instance.__dict__[self.name] = self.func(instance)
  File "/home/python/.virtualenvs/django_cp4/lib/python3.5/site-packages/rest_framework/serializers.py", line 376, in _readable_fields
    field for field in self.fields.values()
  File "/home/python/.virtualenvs/django_cp4/lib/python3.5/site-packages/rest_framework/serializers.py", line 363, in fields
    for key, value in self.get_fields().items():
  File "/home/python/.virtualenvs/django_cp4/lib/python3.5/site-packages/rest_framework/serializers.py", line 1045, in get_fields
    source, info, model, depth
  File "/home/python/.virtualenvs/django_cp4/lib/python3.5/site-packages/rest_framework/serializers.py", line 1190, in build_field
    return self.build_unknown_field(field_name, model_class)
  File "/home/python/.virtualenvs/django_cp4/lib/python3.5/site-packages/rest_framework/serializers.py", line 1302, in build_unknown_field
    (field_name, model_class.__name__)
django.core.exceptions.ImproperlyConfigured: Field name `e_mail` is not valid for model `User`.
ERROR 2018-08-24 19:37:28,185 basehttp 124 "GET /user/ HTTP/1.1" 500 20098
ERROR 2018-08-24 19:37:29,646 exception 135 Internal Server Error: /user/
Traceback (most recent call last):
  File "/home/python/.virtualenvs/django_cp4/lib/python3.5/site-packages/django/core/handlers/exception.py", line 41, in inner
    response = get_response(request)
  File "/home/python/.virtualenvs/django_cp4/lib/python3.5/site-packages/django/core/handlers/base.py", line 187, in _get_response
    response = self.process_exception_by_middleware(e, request)
  File "/home/python/.virtualenvs/django_cp4/lib/python3.5/site-packages/django/core/handlers/base.py", line 185, in _get_response
    response = wrapped_callback(request, *callback_args, **callback_kwargs)
  File "/home/python/.virtualenvs/django_cp4/lib/python3.5/site-packages/django/views/decorators/csrf.py", line 58, in wrapped_view
    return view_func(*args, **kwargs)
  File "/home/python/.virtualenvs/django_cp4/lib/python3.5/site-packages/django/views/generic/base.py", line 68, in view
    return self.dispatch(request, *args, **kwargs)
  File "/home/python/.virtualenvs/django_cp4/lib/python3.5/site-packages/rest_framework/views.py", line 483, in dispatch
    response = self.handle_exception(exc)
  File "/home/python/.virtualenvs/django_cp4/lib/python3.5/site-packages/rest_framework/views.py", line 443, in handle_exception
    self.raise_uncaught_exception(exc)
  File "/home/python/.virtualenvs/django_cp4/lib/python3.5/site-packages/rest_framework/views.py", line 480, in dispatch
    response = handler(request, *args, **kwargs)
  File "/home/python/.virtualenvs/django_cp4/lib/python3.5/site-packages/rest_framework/generics.py", line 210, in get
    return self.retrieve(request, *args, **kwargs)
  File "/home/python/.virtualenvs/django_cp4/lib/python3.5/site-packages/rest_framework/mixins.py", line 58, in retrieve
    return Response(serializer.data)
  File "/home/python/.virtualenvs/django_cp4/lib/python3.5/site-packages/rest_framework/serializers.py", line 560, in data
    ret = super(Serializer, self).data
  File "/home/python/.virtualenvs/django_cp4/lib/python3.5/site-packages/rest_framework/serializers.py", line 262, in data
    self._data = self.to_representation(self.instance)
  File "/home/python/.virtualenvs/django_cp4/lib/python3.5/site-packages/rest_framework/serializers.py", line 510, in to_representation
    fields = self._readable_fields
  File "/home/python/.virtualenvs/django_cp4/lib/python3.5/site-packages/django/utils/functional.py", line 35, in __get__
    res = instance.__dict__[self.name] = self.func(instance)
  File "/home/python/.virtualenvs/django_cp4/lib/python3.5/site-packages/rest_framework/serializers.py", line 376, in _readable_fields
    field for field in self.fields.values()
  File "/home/python/.virtualenvs/django_cp4/lib/python3.5/site-packages/rest_framework/serializers.py", line 363, in fields
    for key, value in self.get_fields().items():
  File "/home/python/.virtualenvs/django_cp4/lib/python3.5/site-packages/rest_framework/serializers.py", line 1045, in get_fields
    source, info, model, depth
  File "/home/python/.virtualenvs/django_cp4/lib/python3.5/site-packages/rest_framework/serializers.py", line 1190, in build_field
    return self.build_unknown_field(field_name, model_class)
  File "/home/python/.virtualenvs/django_cp4/lib/python3.5/site-packages/rest_framework/serializers.py", line 1302, in build_unknown_field
    (field_name, model_class.__name__)
django.core.exceptions.ImproperlyConfigured: Field name `e_mail` is not valid for model `User`.
ERROR 2018-08-24 19:37:29,694 basehttp 124 "GET /user/ HTTP/1.1" 500 20098
INFO 2018-08-24 19:37:32,543 basehttp 124 "GET /oauth/qq/authorization/?next=/ HTTP/1.1" 200 195
INFO 2018-08-24 19:37:46,690 basehttp 124 "GET /oauth/qq/user/?code=0B4633A8AC5C728FD956FCAAAA51617E HTTP/1.1" 200 231
ERROR 2018-08-24 19:37:49,232 exception 135 Internal Server Error: /user/
Traceback (most recent call last):
  File "/home/python/.virtualenvs/django_cp4/lib/python3.5/site-packages/django/core/handlers/exception.py", line 41, in inner
    response = get_response(request)
  File "/home/python/.virtualenvs/django_cp4/lib/python3.5/site-packages/django/core/handlers/base.py", line 187, in _get_response
    response = self.process_exception_by_middleware(e, request)
  File "/home/python/.virtualenvs/django_cp4/lib/python3.5/site-packages/django/core/handlers/base.py", line 185, in _get_response
    response = wrapped_callback(request, *callback_args, **callback_kwargs)
  File "/home/python/.virtualenvs/django_cp4/lib/python3.5/site-packages/django/views/decorators/csrf.py", line 58, in wrapped_view
    return view_func(*args, **kwargs)
  File "/home/python/.virtualenvs/django_cp4/lib/python3.5/site-packages/django/views/generic/base.py", line 68, in view
    return self.dispatch(request, *args, **kwargs)
  File "/home/python/.virtualenvs/django_cp4/lib/python3.5/site-packages/rest_framework/views.py", line 483, in dispatch
    response = self.handle_exception(exc)
  File "/home/python/.virtualenvs/django_cp4/lib/python3.5/site-packages/rest_framework/views.py", line 443, in handle_exception
    self.raise_uncaught_exception(exc)
  File "/home/python/.virtualenvs/django_cp4/lib/python3.5/site-packages/rest_framework/views.py", line 480, in dispatch
    response = handler(request, *args, **kwargs)
  File "/home/python/.virtualenvs/django_cp4/lib/python3.5/site-packages/rest_framework/generics.py", line 210, in get
    return self.retrieve(request, *args, **kwargs)
  File "/home/python/.virtualenvs/django_cp4/lib/python3.5/site-packages/rest_framework/mixins.py", line 58, in retrieve
    return Response(serializer.data)
  File "/home/python/.virtualenvs/django_cp4/lib/python3.5/site-packages/rest_framework/serializers.py", line 560, in data
    ret = super(Serializer, self).data
  File "/home/python/.virtualenvs/django_cp4/lib/python3.5/site-packages/rest_framework/serializers.py", line 262, in data
    self._data = self.to_representation(self.instance)
  File "/home/python/.virtualenvs/django_cp4/lib/python3.5/site-packages/rest_framework/serializers.py", line 510, in to_representation
    fields = self._readable_fields
  File "/home/python/.virtualenvs/django_cp4/lib/python3.5/site-packages/django/utils/functional.py", line 35, in __get__
    res = instance.__dict__[self.name] = self.func(instance)
  File "/home/python/.virtualenvs/django_cp4/lib/python3.5/site-packages/rest_framework/serializers.py", line 376, in _readable_fields
    field for field in self.fields.values()
  File "/home/python/.virtualenvs/django_cp4/lib/python3.5/site-packages/rest_framework/serializers.py", line 363, in fields
    for key, value in self.get_fields().items():
  File "/home/python/.virtualenvs/django_cp4/lib/python3.5/site-packages/rest_framework/serializers.py", line 1045, in get_fields
    source, info, model, depth
  File "/home/python/.virtualenvs/django_cp4/lib/python3.5/site-packages/rest_framework/serializers.py", line 1190, in build_field
    return self.build_unknown_field(field_name, model_class)
  File "/home/python/.virtualenvs/django_cp4/lib/python3.5/site-packages/rest_framework/serializers.py", line 1302, in build_unknown_field
    (field_name, model_class.__name__)
django.core.exceptions.ImproperlyConfigured: Field name `e_mail` is not valid for model `User`.
ERROR 2018-08-24 19:37:49,271 basehttp 124 "GET /user/ HTTP/1.1" 500 20069
ERROR 2018-08-24 19:37:50,679 exception 135 Internal Server Error: /user/
Traceback (most recent call last):
  File "/home/python/.virtualenvs/django_cp4/lib/python3.5/site-packages/django/core/handlers/exception.py", line 41, in inner
    response = get_response(request)
  File "/home/python/.virtualenvs/django_cp4/lib/python3.5/site-packages/django/core/handlers/base.py", line 187, in _get_response
    response = self.process_exception_by_middleware(e, request)
  File "/home/python/.virtualenvs/django_cp4/lib/python3.5/site-packages/django/core/handlers/base.py", line 185, in _get_response
    response = wrapped_callback(request, *callback_args, **callback_kwargs)
  File "/home/python/.virtualenvs/django_cp4/lib/python3.5/site-packages/django/views/decorators/csrf.py", line 58, in wrapped_view
    return view_func(*args, **kwargs)
  File "/home/python/.virtualenvs/django_cp4/lib/python3.5/site-packages/django/views/generic/base.py", line 68, in view
    return self.dispatch(request, *args, **kwargs)
  File "/home/python/.virtualenvs/django_cp4/lib/python3.5/site-packages/rest_framework/views.py", line 483, in dispatch
    response = self.handle_exception(exc)
  File "/home/python/.virtualenvs/django_cp4/lib/python3.5/site-packages/rest_framework/views.py", line 443, in handle_exception
    self.raise_uncaught_exception(exc)
  File "/home/python/.virtualenvs/django_cp4/lib/python3.5/site-packages/rest_framework/views.py", line 480, in dispatch
    response = handler(request, *args, **kwargs)
  File "/home/python/.virtualenvs/django_cp4/lib/python3.5/site-packages/rest_framework/generics.py", line 210, in get
    return self.retrieve(request, *args, **kwargs)
  File "/home/python/.virtualenvs/django_cp4/lib/python3.5/site-packages/rest_framework/mixins.py", line 58, in retrieve
    return Response(serializer.data)
  File "/home/python/.virtualenvs/django_cp4/lib/python3.5/site-packages/rest_framework/serializers.py", line 560, in data
    ret = super(Serializer, self).data
  File "/home/python/.virtualenvs/django_cp4/lib/python3.5/site-packages/rest_framework/serializers.py", line 262, in data
    self._data = self.to_representation(self.instance)
  File "/home/python/.virtualenvs/django_cp4/lib/python3.5/site-packages/rest_framework/serializers.py", line 510, in to_representation
    fields = self._readable_fields
  File "/home/python/.virtualenvs/django_cp4/lib/python3.5/site-packages/django/utils/functional.py", line 35, in __get__
    res = instance.__dict__[self.name] = self.func(instance)
  File "/home/python/.virtualenvs/django_cp4/lib/python3.5/site-packages/rest_framework/serializers.py", line 376, in _readable_fields
    field for field in self.fields.values()
  File "/home/python/.virtualenvs/django_cp4/lib/python3.5/site-packages/rest_framework/serializers.py", line 363, in fields
    for key, value in self.get_fields().items():
  File "/home/python/.virtualenvs/django_cp4/lib/python3.5/site-packages/rest_framework/serializers.py", line 1045, in get_fields
    source, info, model, depth
  File "/home/python/.virtualenvs/django_cp4/lib/python3.5/site-packages/rest_framework/serializers.py", line 1190, in build_field
    return self.build_unknown_field(field_name, model_class)
  File "/home/python/.virtualenvs/django_cp4/lib/python3.5/site-packages/rest_framework/serializers.py", line 1302, in build_unknown_field
    (field_name, model_class.__name__)
django.core.exceptions.ImproperlyConfigured: Field name `e_mail` is not valid for model `User`.
ERROR 2018-08-24 19:37:50,718 basehttp 124 "GET /user/ HTTP/1.1" 500 20102
INFO 2018-08-24 19:39:20,196 basehttp 124 "GET /user/ HTTP/1.1" 200 101
INFO 2018-08-24 19:39:20,205 basehttp 124 "OPTIONS /browse_histories/ HTTP/1.1" 200 0
WARNING 2018-08-24 19:39:20,217 base 152 Not Found: /browse_histories/
WARNING 2018-08-24 19:39:20,218 basehttp 124 "GET /browse_histories/ HTTP/1.1" 404 3478
INFO 2018-08-24 19:39:21,844 basehttp 124 "GET /user/ HTTP/1.1" 200 101
WARNING 2018-08-24 19:39:21,984 base 152 Not Found: /browse_histories/
WARNING 2018-08-24 19:39:21,985 basehttp 124 "GET /browse_histories/ HTTP/1.1" 404 3478
INFO 2018-08-24 19:39:22,481 basehttp 124 "OPTIONS /emails/ HTTP/1.1" 200 0
INFO 2018-08-24 19:39:22,575 basehttp 124 "PUT /emails/ HTTP/1.1" 200 37
WARNING 2018-08-24 19:53:37,071 base 152 Not Found: /
WARNING 2018-08-24 19:53:37,095 basehttp 124 "GET / HTTP/1.1" 404 3403
WARNING 2018-08-24 19:53:37,249 base 152 Not Found: /favicon.ico
WARNING 2018-08-24 19:53:37,260 basehttp 124 "GET /favicon.ico HTTP/1.1" 404 3454
INFO 2018-08-24 19:54:14,303 basehttp 124 "GET /oauth/qq/authorization/?next=/ HTTP/1.1" 200 195
INFO 2018-08-24 19:54:16,236 basehttp 124 "GET /oauth/qq/authorization/?next=/ HTTP/1.1" 200 195
INFO 2018-08-24 19:54:26,229 basehttp 124 "GET /oauth/qq/authorization/?next=/ HTTP/1.1" 200 195
INFO 2018-08-24 20:03:27,981 basehttp 124 "GET /oauth/qq/authorization/?next=/ HTTP/1.1" 200 195
INFO 2018-08-24 20:03:38,968 basehttp 124 "GET /oauth/qq/authorization/?next=/ HTTP/1.1" 200 195
INFO 2018-08-24 20:03:45,244 basehttp 124 "GET /oauth/qq/authorization/?next=/ HTTP/1.1" 200 195
INFO 2018-08-24 20:03:49,204 basehttp 124 "GET /oauth/qq/authorization/?next=/ HTTP/1.1" 200 195
INFO 2018-08-24 20:03:49,731 basehttp 124 "GET /oauth/qq/authorization/?next=/ HTTP/1.1" 200 195
INFO 2018-08-24 20:03:56,672 basehttp 124 "OPTIONS /user/ HTTP/1.1" 200 0
INFO 2018-08-24 20:03:56,776 basehttp 124 "GET /user/ HTTP/1.1" 200 101
INFO 2018-08-24 20:03:56,797 basehttp 124 "OPTIONS /browse_histories/ HTTP/1.1" 200 0
WARNING 2018-08-24 20:03:56,801 base 152 Not Found: /browse_histories/
WARNING 2018-08-24 20:03:56,805 basehttp 124 "GET /browse_histories/ HTTP/1.1" 404 3478
INFO 2018-08-24 20:03:58,008 basehttp 124 "OPTIONS /emails/ HTTP/1.1" 200 0
INFO 2018-08-24 20:03:58,115 basehttp 124 "PUT /emails/ HTTP/1.1" 200 37
INFO 2018-08-24 20:04:02,793 basehttp 124 "GET /emails/verification/?token=eyJpYXQiOjE1MzUxMTIyMzgsImFsZyI6IkhTMjU2IiwiZXhwIjoxNTM1MTk4NjM4fQ.eyJ1c2VyX2lkIjoxLCJlbWFpbCI6ImhvdWppZTk1QGdtYWlsLmNvbSJ9.k1Hgt0u4jWPZxsgruIoo-0PTFFD_yhLkWY29en9ZP4k HTTP/1.1" 200 16
INFO 2018-08-24 20:04:11,877 basehttp 124 "OPTIONS /user/ HTTP/1.1" 200 0
INFO 2018-08-24 20:04:11,975 basehttp 124 "GET /user/ HTTP/1.1" 200 100
INFO 2018-08-24 20:04:12,003 basehttp 124 "OPTIONS /browse_histories/ HTTP/1.1" 200 0
WARNING 2018-08-24 20:04:12,013 base 152 Not Found: /browse_histories/
WARNING 2018-08-24 20:04:12,016 basehttp 124 "GET /browse_histories/ HTTP/1.1" 404 3478
WARNING 2018-08-25 15:03:08,624 base 152 Not Found: /
WARNING 2018-08-25 15:03:08,634 basehttp 124 "GET / HTTP/1.1" 404 3403
WARNING 2018-08-25 15:03:08,773 base 152 Not Found: /favicon.ico
WARNING 2018-08-25 15:03:08,781 basehttp 124 "GET /favicon.ico HTTP/1.1" 404 3454
INFO 2018-08-25 15:03:35,639 basehttp 124 "GET /oauth/qq/authorization/?next=/ HTTP/1.1" 200 195
INFO 2018-08-25 15:03:39,009 basehttp 124 "GET /oauth/qq/authorization/?next=/ HTTP/1.1" 200 195
INFO 2018-08-25 15:03:44,946 basehttp 124 "GET /oauth/qq/authorization/?next=/ HTTP/1.1" 200 195
INFO 2018-08-25 15:03:54,226 basehttp 124 "GET /oauth/qq/authorization/?next=/ HTTP/1.1" 200 195
INFO 2018-08-25 15:04:09,074 basehttp 124 "OPTIONS /user/ HTTP/1.1" 200 0
INFO 2018-08-25 15:04:09,247 basehttp 124 "GET /user/ HTTP/1.1" 200 100
INFO 2018-08-25 15:04:09,259 basehttp 124 "OPTIONS /browse_histories/ HTTP/1.1" 200 0
WARNING 2018-08-25 15:04:09,262 base 152 Not Found: /browse_histories/
WARNING 2018-08-25 15:04:09,262 basehttp 124 "GET /browse_histories/ HTTP/1.1" 404 3478
INFO 2018-08-25 15:04:11,565 basehttp 124 "OPTIONS /addresses/ HTTP/1.1" 200 0
WARNING 2018-08-25 15:04:11,580 base 152 Not Found: /areas/
WARNING 2018-08-25 15:04:11,592 basehttp 124 "GET /areas/ HTTP/1.1" 404 3445
WARNING 2018-08-25 15:04:11,608 base 152 Not Found: /addresses/
WARNING 2018-08-25 15:04:11,610 basehttp 124 "GET /addresses/ HTTP/1.1" 404 3457
INFO 2018-08-25 15:04:15,660 basehttp 124 "GET /user/ HTTP/1.1" 200 100
WARNING 2018-08-25 15:04:15,670 base 152 Not Found: /browse_histories/
WARNING 2018-08-25 15:04:15,684 basehttp 124 "GET /browse_histories/ HTTP/1.1" 404 3478
INFO 2018-08-25 15:04:17,191 basehttp 124 "GET /user/ HTTP/1.1" 200 100
WARNING 2018-08-25 15:04:17,204 base 152 Not Found: /browse_histories/
WARNING 2018-08-25 15:04:17,206 basehttp 124 "GET /browse_histories/ HTTP/1.1" 404 3478
INFO 2018-08-25 16:08:41,470 basehttp 124 "OPTIONS /addresses/ HTTP/1.1" 200 0
WARNING 2018-08-25 16:08:41,562 base 152 Not Found: /addresses/
WARNING 2018-08-25 16:08:41,565 basehttp 124 "GET /addresses/ HTTP/1.1" 404 6707
ERROR 2018-08-25 16:08:41,565 exception 135 Internal Server Error: /areas/
Traceback (most recent call last):
  File "/home/python/.virtualenvs/django_cp4/lib/python3.5/site-packages/django/core/handlers/exception.py", line 41, in inner
    response = get_response(request)
  File "/home/python/.virtualenvs/django_cp4/lib/python3.5/site-packages/django/core/handlers/base.py", line 187, in _get_response
    response = self.process_exception_by_middleware(e, request)
  File "/home/python/.virtualenvs/django_cp4/lib/python3.5/site-packages/django/core/handlers/base.py", line 185, in _get_response
    response = wrapped_callback(request, *callback_args, **callback_kwargs)
  File "/home/python/.virtualenvs/django_cp4/lib/python3.5/site-packages/django/views/decorators/csrf.py", line 58, in wrapped_view
    return view_func(*args, **kwargs)
  File "/home/python/.virtualenvs/django_cp4/lib/python3.5/site-packages/rest_framework/viewsets.py", line 103, in view
    return self.dispatch(request, *args, **kwargs)
  File "/home/python/.virtualenvs/django_cp4/lib/python3.5/site-packages/rest_framework/views.py", line 483, in dispatch
    response = self.handle_exception(exc)
  File "/home/python/.virtualenvs/django_cp4/lib/python3.5/site-packages/rest_framework/views.py", line 443, in handle_exception
    self.raise_uncaught_exception(exc)
  File "/home/python/.virtualenvs/django_cp4/lib/python3.5/site-packages/rest_framework/views.py", line 480, in dispatch
    response = handler(request, *args, **kwargs)
  File "/home/python/.virtualenvs/django_cp4/lib/python3.5/site-packages/rest_framework/mixins.py", line 47, in list
    serializer = self.get_serializer(queryset, many=True)
  File "/home/python/.virtualenvs/django_cp4/lib/python3.5/site-packages/rest_framework/generics.py", line 110, in get_serializer
    serializer_class = self.get_serializer_class()
  File "/home/python/.virtualenvs/django_cp4/lib/python3.5/site-packages/rest_framework/generics.py", line 127, in get_serializer_class
    % self.__class__.__name__
AssertionError: 'AreasViewSet' should either include a `serializer_class` attribute, or override the `get_serializer_class()` method.
ERROR 2018-08-25 16:08:41,653 basehttp 124 "GET /areas/ HTTP/1.1" 500 18625
WARNING 2018-08-25 16:10:59,385 base 152 Not Found: /addresses/
WARNING 2018-08-25 16:10:59,392 basehttp 124 "GET /addresses/ HTTP/1.1" 404 6707
INFO 2018-08-25 16:10:59,399 basehttp 124 "GET /areas/ HTTP/1.1" 200 1204
INFO 2018-08-25 16:11:07,787 basehttp 124 "GET /areas/120000/ HTTP/1.1" 200 74
INFO 2018-08-25 16:11:08,661 basehttp 124 "GET /areas/120100/ HTTP/1.1" 200 572
WARNING 2018-08-25 16:11:19,210 base 152 Not Found: /addresses/
WARNING 2018-08-25 16:11:19,212 basehttp 124 "POST /addresses/ HTTP/1.1" 404 6708
ERROR 2018-08-25 16:11:41,362 exception 135 Internal Server Error: /addresses/
Traceback (most recent call last):
  File "/home/python/.virtualenvs/django_cp4/lib/python3.5/site-packages/django/core/handlers/exception.py", line 41, in inner
    response = get_response(request)
  File "/home/python/.virtualenvs/django_cp4/lib/python3.5/site-packages/django/core/handlers/base.py", line 187, in _get_response
    response = self.process_exception_by_middleware(e, request)
  File "/home/python/.virtualenvs/django_cp4/lib/python3.5/site-packages/django/core/handlers/base.py", line 185, in _get_response
    response = wrapped_callback(request, *callback_args, **callback_kwargs)
  File "/home/python/.virtualenvs/django_cp4/lib/python3.5/site-packages/django/views/decorators/csrf.py", line 58, in wrapped_view
    return view_func(*args, **kwargs)
  File "/home/python/.virtualenvs/django_cp4/lib/python3.5/site-packages/rest_framework/viewsets.py", line 103, in view
    return self.dispatch(request, *args, **kwargs)
  File "/home/python/.virtualenvs/django_cp4/lib/python3.5/site-packages/rest_framework/views.py", line 483, in dispatch
    response = self.handle_exception(exc)
  File "/home/python/.virtualenvs/django_cp4/lib/python3.5/site-packages/rest_framework/views.py", line 443, in handle_exception
    self.raise_uncaught_exception(exc)
  File "/home/python/.virtualenvs/django_cp4/lib/python3.5/site-packages/rest_framework/views.py", line 480, in dispatch
    response = handler(request, *args, **kwargs)
  File "/home/python/Desktop/Django_1/meiduo_api/apps/users/views.py", line 129, in create
    return super().create(request, *args, **kwargs)
  File "/home/python/.virtualenvs/django_cp4/lib/python3.5/site-packages/rest_framework/mixins.py", line 20, in create
    serializer.is_valid(raise_exception=True)
  File "/home/python/.virtualenvs/django_cp4/lib/python3.5/site-packages/rest_framework/serializers.py", line 236, in is_valid
    self._validated_data = self.run_validation(self.initial_data)
  File "/home/python/.virtualenvs/django_cp4/lib/python3.5/site-packages/rest_framework/serializers.py", line 434, in run_validation
    value = self.to_internal_value(data)
  File "/home/python/.virtualenvs/django_cp4/lib/python3.5/site-packages/rest_framework/serializers.py", line 482, in to_internal_value
    fields = self._writable_fields
  File "/home/python/.virtualenvs/django_cp4/lib/python3.5/site-packages/django/utils/functional.py", line 35, in __get__
    res = instance.__dict__[self.name] = self.func(instance)
  File "/home/python/.virtualenvs/django_cp4/lib/python3.5/site-packages/rest_framework/serializers.py", line 370, in _writable_fields
    field for field in self.fields.values() if not field.read_only
  File "/home/python/.virtualenvs/django_cp4/lib/python3.5/site-packages/rest_framework/serializers.py", line 363, in fields
    for key, value in self.get_fields().items():
  File "/home/python/.virtualenvs/django_cp4/lib/python3.5/site-packages/rest_framework/serializers.py", line 1020, in get_fields
    field_names = self.get_field_names(declared_fields, info)
  File "/home/python/.virtualenvs/django_cp4/lib/python3.5/site-packages/rest_framework/serializers.py", line 1148, in get_field_names
    serializer_class=self.__class__.__name__
AssertionError: The field 'is_delete' was included on serializer UserAddressSerializer in the 'exclude' option, but does not match any model field.
ERROR 2018-08-25 16:11:41,421 basehttp 124 "POST /addresses/ HTTP/1.1" 500 20172
ERROR 2018-08-25 16:12:08,071 exception 135 Internal Server Error: /addresses/
Traceback (most recent call last):
  File "/home/python/.virtualenvs/django_cp4/lib/python3.5/site-packages/django/core/handlers/exception.py", line 41, in inner
    response = get_response(request)
  File "/home/python/.virtualenvs/django_cp4/lib/python3.5/site-packages/django/core/handlers/base.py", line 187, in _get_response
    response = self.process_exception_by_middleware(e, request)
  File "/home/python/.virtualenvs/django_cp4/lib/python3.5/site-packages/django/core/handlers/base.py", line 185, in _get_response
    response = wrapped_callback(request, *callback_args, **callback_kwargs)
  File "/home/python/.virtualenvs/django_cp4/lib/python3.5/site-packages/django/views/decorators/csrf.py", line 58, in wrapped_view
    return view_func(*args, **kwargs)
  File "/home/python/.virtualenvs/django_cp4/lib/python3.5/site-packages/rest_framework/viewsets.py", line 103, in view
    return self.dispatch(request, *args, **kwargs)
  File "/home/python/.virtualenvs/django_cp4/lib/python3.5/site-packages/rest_framework/views.py", line 483, in dispatch
    response = self.handle_exception(exc)
  File "/home/python/.virtualenvs/django_cp4/lib/python3.5/site-packages/rest_framework/views.py", line 443, in handle_exception
    self.raise_uncaught_exception(exc)
  File "/home/python/.virtualenvs/django_cp4/lib/python3.5/site-packages/rest_framework/views.py", line 480, in dispatch
    response = handler(request, *args, **kwargs)
  File "/home/python/Desktop/Django_1/meiduo_api/apps/users/views.py", line 129, in create
    return super().create(request, *args, **kwargs)
  File "/home/python/.virtualenvs/django_cp4/lib/python3.5/site-packages/rest_framework/mixins.py", line 20, in create
    serializer.is_valid(raise_exception=True)
  File "/home/python/.virtualenvs/django_cp4/lib/python3.5/site-packages/rest_framework/serializers.py", line 236, in is_valid
    self._validated_data = self.run_validation(self.initial_data)
  File "/home/python/.virtualenvs/django_cp4/lib/python3.5/site-packages/rest_framework/serializers.py", line 434, in run_validation
    value = self.to_internal_value(data)
  File "/home/python/.virtualenvs/django_cp4/lib/python3.5/site-packages/rest_framework/serializers.py", line 482, in to_internal_value
    fields = self._writable_fields
  File "/home/python/.virtualenvs/django_cp4/lib/python3.5/site-packages/django/utils/functional.py", line 35, in __get__
    res = instance.__dict__[self.name] = self.func(instance)
  File "/home/python/.virtualenvs/django_cp4/lib/python3.5/site-packages/rest_framework/serializers.py", line 370, in _writable_fields
    field for field in self.fields.values() if not field.read_only
  File "/home/python/.virtualenvs/django_cp4/lib/python3.5/site-packages/rest_framework/serializers.py", line 363, in fields
    for key, value in self.get_fields().items():
  File "/home/python/.virtualenvs/django_cp4/lib/python3.5/site-packages/rest_framework/serializers.py", line 1020, in get_fields
    field_names = self.get_field_names(declared_fields, info)
  File "/home/python/.virtualenvs/django_cp4/lib/python3.5/site-packages/rest_framework/serializers.py", line 1148, in get_field_names
    serializer_class=self.__class__.__name__
AssertionError: The field 'is_delete' was included on serializer UserAddressSerializer in the 'exclude' option, but does not match any model field.
ERROR 2018-08-25 16:12:08,096 basehttp 124 "POST /addresses/ HTTP/1.1" 500 20172
INFO 2018-08-25 16:12:10,956 basehttp 124 "GET /areas/ HTTP/1.1" 200 1204
INFO 2018-08-25 16:12:10,962 basehttp 124 "GET /addresses/ HTTP/1.1" 200 64
INFO 2018-08-25 16:13:42,606 basehttp 124 "GET /areas/ HTTP/1.1" 200 1204
INFO 2018-08-25 16:13:42,608 basehttp 124 "GET /addresses/ HTTP/1.1" 200 64
INFO 2018-08-25 16:13:54,433 basehttp 124 "GET /areas/110000/ HTTP/1.1" 200 74
INFO 2018-08-25 16:13:55,307 basehttp 124 "GET /areas/110100/ HTTP/1.1" 200 575
ERROR 2018-08-25 16:14:03,465 exception 135 Internal Server Error: /addresses/
Traceback (most recent call last):
  File "/home/python/.virtualenvs/django_cp4/lib/python3.5/site-packages/django/core/handlers/exception.py", line 41, in inner
    response = get_response(request)
  File "/home/python/.virtualenvs/django_cp4/lib/python3.5/site-packages/django/core/handlers/base.py", line 187, in _get_response
    response = self.process_exception_by_middleware(e, request)
  File "/home/python/.virtualenvs/django_cp4/lib/python3.5/site-packages/django/core/handlers/base.py", line 185, in _get_response
    response = wrapped_callback(request, *callback_args, **callback_kwargs)
  File "/home/python/.virtualenvs/django_cp4/lib/python3.5/site-packages/django/views/decorators/csrf.py", line 58, in wrapped_view
    return view_func(*args, **kwargs)
  File "/home/python/.virtualenvs/django_cp4/lib/python3.5/site-packages/rest_framework/viewsets.py", line 103, in view
    return self.dispatch(request, *args, **kwargs)
  File "/home/python/.virtualenvs/django_cp4/lib/python3.5/site-packages/rest_framework/views.py", line 483, in dispatch
    response = self.handle_exception(exc)
  File "/home/python/.virtualenvs/django_cp4/lib/python3.5/site-packages/rest_framework/views.py", line 443, in handle_exception
    self.raise_uncaught_exception(exc)
  File "/home/python/.virtualenvs/django_cp4/lib/python3.5/site-packages/rest_framework/views.py", line 480, in dispatch
    response = handler(request, *args, **kwargs)
  File "/home/python/Desktop/Django_1/meiduo_api/apps/users/views.py", line 129, in create
    return super().create(request, *args, **kwargs)
  File "/home/python/.virtualenvs/django_cp4/lib/python3.5/site-packages/rest_framework/mixins.py", line 20, in create
    serializer.is_valid(raise_exception=True)
  File "/home/python/.virtualenvs/django_cp4/lib/python3.5/site-packages/rest_framework/serializers.py", line 236, in is_valid
    self._validated_data = self.run_validation(self.initial_data)
  File "/home/python/.virtualenvs/django_cp4/lib/python3.5/site-packages/rest_framework/serializers.py", line 434, in run_validation
    value = self.to_internal_value(data)
  File "/home/python/.virtualenvs/django_cp4/lib/python3.5/site-packages/rest_framework/serializers.py", line 482, in to_internal_value
    fields = self._writable_fields
  File "/home/python/.virtualenvs/django_cp4/lib/python3.5/site-packages/django/utils/functional.py", line 35, in __get__
    res = instance.__dict__[self.name] = self.func(instance)
  File "/home/python/.virtualenvs/django_cp4/lib/python3.5/site-packages/rest_framework/serializers.py", line 370, in _writable_fields
    field for field in self.fields.values() if not field.read_only
  File "/home/python/.virtualenvs/django_cp4/lib/python3.5/site-packages/rest_framework/serializers.py", line 363, in fields
    for key, value in self.get_fields().items():
  File "/home/python/.virtualenvs/django_cp4/lib/python3.5/site-packages/rest_framework/serializers.py", line 1020, in get_fields
    field_names = self.get_field_names(declared_fields, info)
  File "/home/python/.virtualenvs/django_cp4/lib/python3.5/site-packages/rest_framework/serializers.py", line 1148, in get_field_names
    serializer_class=self.__class__.__name__
AssertionError: The field 'is_delete' was included on serializer UserAddressSerializer in the 'exclude' option, but does not match any model field.
ERROR 2018-08-25 16:14:03,494 basehttp 124 "POST /addresses/ HTTP/1.1" 500 20172
ERROR 2018-08-25 16:16:57,632 exception 135 Internal Server Error: /addresses/
Traceback (most recent call last):
  File "/home/python/.virtualenvs/django_cp4/lib/python3.5/site-packages/django/core/handlers/exception.py", line 41, in inner
    response = get_response(request)
  File "/home/python/.virtualenvs/django_cp4/lib/python3.5/site-packages/django/core/handlers/base.py", line 187, in _get_response
    response = self.process_exception_by_middleware(e, request)
  File "/home/python/.virtualenvs/django_cp4/lib/python3.5/site-packages/django/core/handlers/base.py", line 185, in _get_response
    response = wrapped_callback(request, *callback_args, **callback_kwargs)
  File "/home/python/.virtualenvs/django_cp4/lib/python3.5/site-packages/django/views/decorators/csrf.py", line 58, in wrapped_view
    return view_func(*args, **kwargs)
  File "/home/python/.virtualenvs/django_cp4/lib/python3.5/site-packages/rest_framework/viewsets.py", line 103, in view
    return self.dispatch(request, *args, **kwargs)
  File "/home/python/.virtualenvs/django_cp4/lib/python3.5/site-packages/rest_framework/views.py", line 483, in dispatch
    response = self.handle_exception(exc)
  File "/home/python/.virtualenvs/django_cp4/lib/python3.5/site-packages/rest_framework/views.py", line 443, in handle_exception
    self.raise_uncaught_exception(exc)
  File "/home/python/.virtualenvs/django_cp4/lib/python3.5/site-packages/rest_framework/views.py", line 480, in dispatch
    response = handler(request, *args, **kwargs)
  File "/home/python/Desktop/Django_1/meiduo_api/apps/users/views.py", line 132, in create
    return super().create(request, *args, **kwargs)
  File "/home/python/.virtualenvs/django_cp4/lib/python3.5/site-packages/rest_framework/mixins.py", line 20, in create
    serializer.is_valid(raise_exception=True)
  File "/home/python/.virtualenvs/django_cp4/lib/python3.5/site-packages/rest_framework/serializers.py", line 236, in is_valid
    self._validated_data = self.run_validation(self.initial_data)
  File "/home/python/.virtualenvs/django_cp4/lib/python3.5/site-packages/rest_framework/serializers.py", line 434, in run_validation
    value = self.to_internal_value(data)
  File "/home/python/.virtualenvs/django_cp4/lib/python3.5/site-packages/rest_framework/serializers.py", line 482, in to_internal_value
    fields = self._writable_fields
  File "/home/python/.virtualenvs/django_cp4/lib/python3.5/site-packages/django/utils/functional.py", line 35, in __get__
    res = instance.__dict__[self.name] = self.func(instance)
  File "/home/python/.virtualenvs/django_cp4/lib/python3.5/site-packages/rest_framework/serializers.py", line 370, in _writable_fields
    field for field in self.fields.values() if not field.read_only
  File "/home/python/.virtualenvs/django_cp4/lib/python3.5/site-packages/rest_framework/serializers.py", line 363, in fields
    for key, value in self.get_fields().items():
  File "/home/python/.virtualenvs/django_cp4/lib/python3.5/site-packages/rest_framework/serializers.py", line 1020, in get_fields
    field_names = self.get_field_names(declared_fields, info)
  File "/home/python/.virtualenvs/django_cp4/lib/python3.5/site-packages/rest_framework/serializers.py", line 1148, in get_field_names
    serializer_class=self.__class__.__name__
AssertionError: The field 'is_delete' was included on serializer UserAddressSerializer in the 'exclude' option, but does not match any model field.
ERROR 2018-08-25 16:16:57,658 basehttp 124 "POST /addresses/ HTTP/1.1" 500 20172
ERROR 2018-08-25 16:16:58,817 exception 135 Internal Server Error: /addresses/
Traceback (most recent call last):
  File "/home/python/.virtualenvs/django_cp4/lib/python3.5/site-packages/django/core/handlers/exception.py", line 41, in inner
    response = get_response(request)
  File "/home/python/.virtualenvs/django_cp4/lib/python3.5/site-packages/django/core/handlers/base.py", line 187, in _get_response
    response = self.process_exception_by_middleware(e, request)
  File "/home/python/.virtualenvs/django_cp4/lib/python3.5/site-packages/django/core/handlers/base.py", line 185, in _get_response
    response = wrapped_callback(request, *callback_args, **callback_kwargs)
  File "/home/python/.virtualenvs/django_cp4/lib/python3.5/site-packages/django/views/decorators/csrf.py", line 58, in wrapped_view
    return view_func(*args, **kwargs)
  File "/home/python/.virtualenvs/django_cp4/lib/python3.5/site-packages/rest_framework/viewsets.py", line 103, in view
    return self.dispatch(request, *args, **kwargs)
  File "/home/python/.virtualenvs/django_cp4/lib/python3.5/site-packages/rest_framework/views.py", line 483, in dispatch
    response = self.handle_exception(exc)
  File "/home/python/.virtualenvs/django_cp4/lib/python3.5/site-packages/rest_framework/views.py", line 443, in handle_exception
    self.raise_uncaught_exception(exc)
  File "/home/python/.virtualenvs/django_cp4/lib/python3.5/site-packages/rest_framework/views.py", line 480, in dispatch
    response = handler(request, *args, **kwargs)
  File "/home/python/Desktop/Django_1/meiduo_api/apps/users/views.py", line 132, in create
    return super().create(request, *args, **kwargs)
  File "/home/python/.virtualenvs/django_cp4/lib/python3.5/site-packages/rest_framework/mixins.py", line 20, in create
    serializer.is_valid(raise_exception=True)
  File "/home/python/.virtualenvs/django_cp4/lib/python3.5/site-packages/rest_framework/serializers.py", line 236, in is_valid
    self._validated_data = self.run_validation(self.initial_data)
  File "/home/python/.virtualenvs/django_cp4/lib/python3.5/site-packages/rest_framework/serializers.py", line 434, in run_validation
    value = self.to_internal_value(data)
  File "/home/python/.virtualenvs/django_cp4/lib/python3.5/site-packages/rest_framework/serializers.py", line 482, in to_internal_value
    fields = self._writable_fields
  File "/home/python/.virtualenvs/django_cp4/lib/python3.5/site-packages/django/utils/functional.py", line 35, in __get__
    res = instance.__dict__[self.name] = self.func(instance)
  File "/home/python/.virtualenvs/django_cp4/lib/python3.5/site-packages/rest_framework/serializers.py", line 370, in _writable_fields
    field for field in self.fields.values() if not field.read_only
  File "/home/python/.virtualenvs/django_cp4/lib/python3.5/site-packages/rest_framework/serializers.py", line 363, in fields
    for key, value in self.get_fields().items():
  File "/home/python/.virtualenvs/django_cp4/lib/python3.5/site-packages/rest_framework/serializers.py", line 1020, in get_fields
    field_names = self.get_field_names(declared_fields, info)
  File "/home/python/.virtualenvs/django_cp4/lib/python3.5/site-packages/rest_framework/serializers.py", line 1148, in get_field_names
    serializer_class=self.__class__.__name__
AssertionError: The field 'is_delete' was included on serializer UserAddressSerializer in the 'exclude' option, but does not match any model field.
ERROR 2018-08-25 16:16:58,832 basehttp 124 "POST /addresses/ HTTP/1.1" 500 20172
ERROR 2018-08-25 16:16:58,986 exception 135 Internal Server Error: /addresses/
Traceback (most recent call last):
  File "/home/python/.virtualenvs/django_cp4/lib/python3.5/site-packages/django/core/handlers/exception.py", line 41, in inner
    response = get_response(request)
  File "/home/python/.virtualenvs/django_cp4/lib/python3.5/site-packages/django/core/handlers/base.py", line 187, in _get_response
    response = self.process_exception_by_middleware(e, request)
  File "/home/python/.virtualenvs/django_cp4/lib/python3.5/site-packages/django/core/handlers/base.py", line 185, in _get_response
    response = wrapped_callback(request, *callback_args, **callback_kwargs)
  File "/home/python/.virtualenvs/django_cp4/lib/python3.5/site-packages/django/views/decorators/csrf.py", line 58, in wrapped_view
    return view_func(*args, **kwargs)
  File "/home/python/.virtualenvs/django_cp4/lib/python3.5/site-packages/rest_framework/viewsets.py", line 103, in view
    return self.dispatch(request, *args, **kwargs)
  File "/home/python/.virtualenvs/django_cp4/lib/python3.5/site-packages/rest_framework/views.py", line 483, in dispatch
    response = self.handle_exception(exc)
  File "/home/python/.virtualenvs/django_cp4/lib/python3.5/site-packages/rest_framework/views.py", line 443, in handle_exception
    self.raise_uncaught_exception(exc)
  File "/home/python/.virtualenvs/django_cp4/lib/python3.5/site-packages/rest_framework/views.py", line 480, in dispatch
    response = handler(request, *args, **kwargs)
  File "/home/python/Desktop/Django_1/meiduo_api/apps/users/views.py", line 132, in create
    return super().create(request, *args, **kwargs)
  File "/home/python/.virtualenvs/django_cp4/lib/python3.5/site-packages/rest_framework/mixins.py", line 20, in create
    serializer.is_valid(raise_exception=True)
  File "/home/python/.virtualenvs/django_cp4/lib/python3.5/site-packages/rest_framework/serializers.py", line 236, in is_valid
    self._validated_data = self.run_validation(self.initial_data)
  File "/home/python/.virtualenvs/django_cp4/lib/python3.5/site-packages/rest_framework/serializers.py", line 434, in run_validation
    value = self.to_internal_value(data)
  File "/home/python/.virtualenvs/django_cp4/lib/python3.5/site-packages/rest_framework/serializers.py", line 482, in to_internal_value
    fields = self._writable_fields
  File "/home/python/.virtualenvs/django_cp4/lib/python3.5/site-packages/django/utils/functional.py", line 35, in __get__
    res = instance.__dict__[self.name] = self.func(instance)
  File "/home/python/.virtualenvs/django_cp4/lib/python3.5/site-packages/rest_framework/serializers.py", line 370, in _writable_fields
    field for field in self.fields.values() if not field.read_only
  File "/home/python/.virtualenvs/django_cp4/lib/python3.5/site-packages/rest_framework/serializers.py", line 363, in fields
    for key, value in self.get_fields().items():
  File "/home/python/.virtualenvs/django_cp4/lib/python3.5/site-packages/rest_framework/serializers.py", line 1020, in get_fields
    field_names = self.get_field_names(declared_fields, info)
  File "/home/python/.virtualenvs/django_cp4/lib/python3.5/site-packages/rest_framework/serializers.py", line 1148, in get_field_names
    serializer_class=self.__class__.__name__
AssertionError: The field 'is_delete' was included on serializer UserAddressSerializer in the 'exclude' option, but does not match any model field.
ERROR 2018-08-25 16:16:59,005 basehttp 124 "POST /addresses/ HTTP/1.1" 500 20172
INFO 2018-08-25 16:18:37,543 basehttp 124 "POST /addresses/ HTTP/1.1" 201 221
INFO 2018-08-25 16:18:39,139 basehttp 124 "OPTIONS /addresses/1/status/ HTTP/1.1" 200 0
INFO 2018-08-25 16:18:39,161 basehttp 124 "PUT /addresses/1/status/ HTTP/1.1" 200 16
INFO 2018-08-25 19:59:00,727 basehttp 124 "GET / HTTP/1.1" 200 5183
INFO 2018-08-25 19:59:00,778 basehttp 124 "GET /static/rest_framework/css/default.css HTTP/1.1" 304 0
INFO 2018-08-25 19:59:00,778 basehttp 124 "GET /static/rest_framework/css/prettify.css HTTP/1.1" 304 0
INFO 2018-08-25 19:59:00,782 basehttp 124 "GET /static/rest_framework/css/bootstrap.min.css HTTP/1.1" 304 0
INFO 2018-08-25 19:59:00,801 basehttp 124 "GET /static/rest_framework/js/jquery-3.3.1.min.js HTTP/1.1" 304 0
INFO 2018-08-25 19:59:00,809 basehttp 124 "GET /static/rest_framework/js/ajax-form.js HTTP/1.1" 304 0
INFO 2018-08-25 19:59:00,816 basehttp 124 "GET /static/rest_framework/css/bootstrap-tweaks.css HTTP/1.1" 304 0
INFO 2018-08-25 19:59:00,834 basehttp 124 "GET /static/rest_framework/js/csrf.js HTTP/1.1" 304 0
INFO 2018-08-25 19:59:00,847 basehttp 124 "GET /static/rest_framework/js/bootstrap.min.js HTTP/1.1" 304 0
INFO 2018-08-25 19:59:00,849 basehttp 124 "GET /static/rest_framework/js/prettify-min.js HTTP/1.1" 304 0
INFO 2018-08-25 19:59:00,854 basehttp 124 "GET /static/rest_framework/js/default.js HTTP/1.1" 304 0
INFO 2018-08-25 19:59:01,082 basehttp 124 "GET /static/rest_framework/img/grid.png HTTP/1.1" 304 0
WARNING 2018-08-25 19:59:01,477 base 152 Not Found: /favicon.ico
WARNING 2018-08-25 19:59:01,488 basehttp 124 "GET /favicon.ico HTTP/1.1" 404 6736
